2024-06-14 11:49:38 - INFO - Start execution in us-east-1 N=5 JsonFile=instance_info.json
2024-06-14 11:49:38 - INFO - Start execution in sa-east-1 N=5 JsonFile=instance_info.json
2024-06-14 11:49:38 - ERROR - Error getting price for c7a.12xlarge
Traceback (most recent call last):
  File "/home/miguelflj/Documentos/Mestrado/awsbench/awsbench/awsbench.py", line 189, in benchmark
    ondemand_price = aws.get_price_ondemand(region, instance_type)
  File "/home/miguelflj/Documentos/Mestrado/awsbench/awsbench/aws_bench/pricing_handler.py", line 26, in get_price_ondemand
    od = json.loads(data['PriceList'][0])['terms']['OnDemand']
IndexError: list index out of range
2024-06-14 11:49:39 - ERROR - Error in sa-east-1a: An error occurred (Unsupported) when calling the RunInstances operation: The requested configuration is currently not supported. Please check the documentation for supported configurations.
Traceback (most recent call last):
  File "/home/miguelflj/Documentos/Mestrado/awsbench/awsbench/awsbench.py", line 98, in start_instance
    instances = ec2.create_instances(
  File "/home/miguelflj/.local/lib/python3.10/site-packages/boto3/resources/factory.py", line 581, in do_action
    response = action(self, *args, **kwargs)
  File "/home/miguelflj/.local/lib/python3.10/site-packages/boto3/resources/action.py", line 88, in __call__
    response = getattr(parent.meta.client, operation_name)(*args, **params)
  File "/home/miguelflj/.local/lib/python3.10/site-packages/botocore/client.py", line 565, in _api_call
    return self._make_api_call(operation_name, kwargs)
  File "/home/miguelflj/.local/lib/python3.10/site-packages/botocore/client.py", line 1021, in _make_api_call
    raise error_class(parsed_response, operation_name)
botocore.exceptions.ClientError: An error occurred (Unsupported) when calling the RunInstances operation: The requested configuration is currently not supported. Please check the documentation for supported configurations.
2024-06-14 11:49:40 - ERROR - Error in sa-east-1b: An error occurred (Unsupported) when calling the RunInstances operation: The requested configuration is currently not supported. Please check the documentation for supported configurations.
Traceback (most recent call last):
  File "/home/miguelflj/Documentos/Mestrado/awsbench/awsbench/awsbench.py", line 98, in start_instance
    instances = ec2.create_instances(
  File "/home/miguelflj/.local/lib/python3.10/site-packages/boto3/resources/factory.py", line 581, in do_action
    response = action(self, *args, **kwargs)
  File "/home/miguelflj/.local/lib/python3.10/site-packages/boto3/resources/action.py", line 88, in __call__
    response = getattr(parent.meta.client, operation_name)(*args, **params)
  File "/home/miguelflj/.local/lib/python3.10/site-packages/botocore/client.py", line 565, in _api_call
    return self._make_api_call(operation_name, kwargs)
  File "/home/miguelflj/.local/lib/python3.10/site-packages/botocore/client.py", line 1021, in _make_api_call
    raise error_class(parsed_response, operation_name)
botocore.exceptions.ClientError: An error occurred (Unsupported) when calling the RunInstances operation: The requested configuration is currently not supported. Please check the documentation for supported configurations.
2024-06-14 11:49:41 - ERROR - Error in sa-east-1c: An error occurred (Unsupported) when calling the RunInstances operation: The requested configuration is currently not supported. Please check the documentation for supported configurations.
Traceback (most recent call last):
  File "/home/miguelflj/Documentos/Mestrado/awsbench/awsbench/awsbench.py", line 98, in start_instance
    instances = ec2.create_instances(
  File "/home/miguelflj/.local/lib/python3.10/site-packages/boto3/resources/factory.py", line 581, in do_action
    response = action(self, *args, **kwargs)
  File "/home/miguelflj/.local/lib/python3.10/site-packages/boto3/resources/action.py", line 88, in __call__
    response = getattr(parent.meta.client, operation_name)(*args, **params)
  File "/home/miguelflj/.local/lib/python3.10/site-packages/botocore/client.py", line 565, in _api_call
    return self._make_api_call(operation_name, kwargs)
  File "/home/miguelflj/.local/lib/python3.10/site-packages/botocore/client.py", line 1021, in _make_api_call
    raise error_class(parsed_response, operation_name)
botocore.exceptions.ClientError: An error occurred (Unsupported) when calling the RunInstances operation: The requested configuration is currently not supported. Please check the documentation for supported configurations.
2024-06-14 11:49:41 - ERROR - Error in sa-east-1d: An error occurred (InvalidParameterValue) when calling the RunInstances operation: Invalid availability zone: [sa-east-1d]
Traceback (most recent call last):
  File "/home/miguelflj/Documentos/Mestrado/awsbench/awsbench/awsbench.py", line 98, in start_instance
    instances = ec2.create_instances(
  File "/home/miguelflj/.local/lib/python3.10/site-packages/boto3/resources/factory.py", line 581, in do_action
    response = action(self, *args, **kwargs)
  File "/home/miguelflj/.local/lib/python3.10/site-packages/boto3/resources/action.py", line 88, in __call__
    response = getattr(parent.meta.client, operation_name)(*args, **params)
  File "/home/miguelflj/.local/lib/python3.10/site-packages/botocore/client.py", line 565, in _api_call
    return self._make_api_call(operation_name, kwargs)
  File "/home/miguelflj/.local/lib/python3.10/site-packages/botocore/client.py", line 1021, in _make_api_call
    raise error_class(parsed_response, operation_name)
botocore.exceptions.ClientError: An error occurred (InvalidParameterValue) when calling the RunInstances operation: Invalid availability zone: [sa-east-1d]
2024-06-14 11:49:41 - ERROR - An exception occurred:name 'enchmarkConfig' is not defined
Traceback (most recent call last):
  File "/home/miguelflj/Documentos/Mestrado/awsbench/awsbench/awsbench.py", line 98, in start_instance
    instances = ec2.create_instances(
  File "/home/miguelflj/.local/lib/python3.10/site-packages/boto3/resources/factory.py", line 581, in do_action
    response = action(self, *args, **kwargs)
  File "/home/miguelflj/.local/lib/python3.10/site-packages/boto3/resources/action.py", line 88, in __call__
    response = getattr(parent.meta.client, operation_name)(*args, **params)
  File "/home/miguelflj/.local/lib/python3.10/site-packages/botocore/client.py", line 565, in _api_call
    return self._make_api_call(operation_name, kwargs)
  File "/home/miguelflj/.local/lib/python3.10/site-packages/botocore/client.py", line 1021, in _make_api_call
    raise error_class(parsed_response, operation_name)
botocore.exceptions.ClientError: An error occurred (InvalidParameterValue) when calling the RunInstances operation: Invalid availability zone: [sa-east-1d]

During handling of the above exception, another exception occurred:

Traceback (most recent call last):
  File "/home/miguelflj/Documentos/Mestrado/awsbench/awsbench/awsbench.py", line 196, in benchmark
    instance = start_instance(region, instance_type)
  File "/home/miguelflj/Documentos/Mestrado/awsbench/awsbench/awsbench.py", line 132, in start_instance
    enchmarkConfig.STATUS = 'Error'
NameError: name 'enchmarkConfig' is not defined
2024-06-14 11:49:52 - ERROR - Error in us-east-1a: An error occurred (InsufficientInstanceCapacity) when calling the RunInstances operation (reached max retries: 4): We currently do not have sufficient c7a.12xlarge capacity in zones with support for 'gp3' volumes. Our system will be working on provisioning additional capacity.
Traceback (most recent call last):
  File "/home/miguelflj/Documentos/Mestrado/awsbench/awsbench/awsbench.py", line 98, in start_instance
    instances = ec2.create_instances(
  File "/home/miguelflj/.local/lib/python3.10/site-packages/boto3/resources/factory.py", line 581, in do_action
    response = action(self, *args, **kwargs)
  File "/home/miguelflj/.local/lib/python3.10/site-packages/boto3/resources/action.py", line 88, in __call__
    response = getattr(parent.meta.client, operation_name)(*args, **params)
  File "/home/miguelflj/.local/lib/python3.10/site-packages/botocore/client.py", line 565, in _api_call
    return self._make_api_call(operation_name, kwargs)
  File "/home/miguelflj/.local/lib/python3.10/site-packages/botocore/client.py", line 1021, in _make_api_call
    raise error_class(parsed_response, operation_name)
botocore.exceptions.ClientError: An error occurred (InsufficientInstanceCapacity) when calling the RunInstances operation (reached max retries: 4): We currently do not have sufficient c7a.12xlarge capacity in zones with support for 'gp3' volumes. Our system will be working on provisioning additional capacity.
2024-06-14 11:50:03 - INFO - Connected (version 2.0, client OpenSSH_9.6p1)
2024-06-14 11:50:03 - INFO - Authentication (publickey) successful!
2024-06-14 11:50:05 - ERROR - Error in us-east-1b: An error occurred (InsufficientInstanceCapacity) when calling the RunInstances operation (reached max retries: 4): We currently do not have sufficient c7a.12xlarge capacity in zones with support for 'gp3' volumes. Our system will be working on provisioning additional capacity.
Traceback (most recent call last):
  File "/home/miguelflj/Documentos/Mestrado/awsbench/awsbench/awsbench.py", line 98, in start_instance
    instances = ec2.create_instances(
  File "/home/miguelflj/.local/lib/python3.10/site-packages/boto3/resources/factory.py", line 581, in do_action
    response = action(self, *args, **kwargs)
  File "/home/miguelflj/.local/lib/python3.10/site-packages/boto3/resources/action.py", line 88, in __call__
    response = getattr(parent.meta.client, operation_name)(*args, **params)
  File "/home/miguelflj/.local/lib/python3.10/site-packages/botocore/client.py", line 565, in _api_call
    return self._make_api_call(operation_name, kwargs)
  File "/home/miguelflj/.local/lib/python3.10/site-packages/botocore/client.py", line 1021, in _make_api_call
    raise error_class(parsed_response, operation_name)
botocore.exceptions.ClientError: An error occurred (InsufficientInstanceCapacity) when calling the RunInstances operation (reached max retries: 4): We currently do not have sufficient c7a.12xlarge capacity in zones with support for 'gp3' volumes. Our system will be working on provisioning additional capacity.
2024-06-14 11:50:15 - ERROR - Error in us-east-1c: An error occurred (InsufficientInstanceCapacity) when calling the RunInstances operation (reached max retries: 4): We currently do not have sufficient c7a.12xlarge capacity in zones with support for 'gp3' volumes. Our system will be working on provisioning additional capacity.
Traceback (most recent call last):
  File "/home/miguelflj/Documentos/Mestrado/awsbench/awsbench/awsbench.py", line 98, in start_instance
    instances = ec2.create_instances(
  File "/home/miguelflj/.local/lib/python3.10/site-packages/boto3/resources/factory.py", line 581, in do_action
    response = action(self, *args, **kwargs)
  File "/home/miguelflj/.local/lib/python3.10/site-packages/boto3/resources/action.py", line 88, in __call__
    response = getattr(parent.meta.client, operation_name)(*args, **params)
  File "/home/miguelflj/.local/lib/python3.10/site-packages/botocore/client.py", line 565, in _api_call
    return self._make_api_call(operation_name, kwargs)
  File "/home/miguelflj/.local/lib/python3.10/site-packages/botocore/client.py", line 1021, in _make_api_call
    raise error_class(parsed_response, operation_name)
botocore.exceptions.ClientError: An error occurred (InsufficientInstanceCapacity) when calling the RunInstances operation (reached max retries: 4): We currently do not have sufficient c7a.12xlarge capacity in zones with support for 'gp3' volumes. Our system will be working on provisioning additional capacity.
2024-06-14 11:50:38 - INFO - Connected (version 2.0, client OpenSSH_9.6p1)
2024-06-14 11:50:38 - INFO - Authentication (publickey) successful!
2024-06-14 11:50:38 - INFO - Connected (version 2.0, client OpenSSH_9.6p1)
2024-06-14 11:50:39 - INFO - Authentication (publickey) successful!
2024-06-14 11:51:12 - INFO - Connected (version 2.0, client OpenSSH_9.6p1)
2024-06-14 11:51:12 - INFO - Authentication (publickey) successful!
2024-06-14 11:51:15 - INFO - Connected (version 2.0, client OpenSSH_9.6p1)
2024-06-14 11:51:15 - INFO - Authentication (publickey) successful!
2024-06-14 11:51:46 - INFO - Connected (version 2.0, client OpenSSH_9.6p1)
2024-06-14 11:51:46 - INFO - Authentication (publickey) successful!
2024-06-14 11:51:50 - INFO - Connected (version 2.0, client OpenSSH_9.6p1)
2024-06-14 11:51:50 - INFO - Authentication (publickey) successful!
2024-06-14 11:52:20 - INFO - Connected (version 2.0, client OpenSSH_9.6p1)
2024-06-14 11:52:20 - INFO - Authentication (publickey) successful!
2024-06-14 11:52:24 - INFO - Connected (version 2.0, client OpenSSH_9.6p1)
2024-06-14 11:52:25 - INFO - Authentication (publickey) successful!
2024-06-14 11:52:59 - INFO - Connected (version 2.0, client OpenSSH_9.6p1)
2024-06-14 11:53:00 - INFO - Authentication (publickey) successful!
2024-06-14 11:54:26 - ERROR - Error getting price for c7g.12xlarge
Traceback (most recent call last):
  File "/home/miguelflj/Documentos/Mestrado/awsbench/awsbench/awsbench.py", line 189, in benchmark
    ondemand_price = aws.get_price_ondemand(region, instance_type)
  File "/home/miguelflj/Documentos/Mestrado/awsbench/awsbench/aws_bench/pricing_handler.py", line 26, in get_price_ondemand
    od = json.loads(data['PriceList'][0])['terms']['OnDemand']
IndexError: list index out of range
2024-06-14 11:54:27 - ERROR - Error in sa-east-1a: An error occurred (Unsupported) when calling the RunInstances operation: The requested configuration is currently not supported. Please check the documentation for supported configurations.
Traceback (most recent call last):
  File "/home/miguelflj/Documentos/Mestrado/awsbench/awsbench/awsbench.py", line 98, in start_instance
    instances = ec2.create_instances(
  File "/home/miguelflj/.local/lib/python3.10/site-packages/boto3/resources/factory.py", line 581, in do_action
    response = action(self, *args, **kwargs)
  File "/home/miguelflj/.local/lib/python3.10/site-packages/boto3/resources/action.py", line 88, in __call__
    response = getattr(parent.meta.client, operation_name)(*args, **params)
  File "/home/miguelflj/.local/lib/python3.10/site-packages/botocore/client.py", line 565, in _api_call
    return self._make_api_call(operation_name, kwargs)
  File "/home/miguelflj/.local/lib/python3.10/site-packages/botocore/client.py", line 1021, in _make_api_call
    raise error_class(parsed_response, operation_name)
botocore.exceptions.ClientError: An error occurred (Unsupported) when calling the RunInstances operation: The requested configuration is currently not supported. Please check the documentation for supported configurations.
2024-06-14 11:54:28 - ERROR - Error in sa-east-1b: An error occurred (Unsupported) when calling the RunInstances operation: The requested configuration is currently not supported. Please check the documentation for supported configurations.
Traceback (most recent call last):
  File "/home/miguelflj/Documentos/Mestrado/awsbench/awsbench/awsbench.py", line 98, in start_instance
    instances = ec2.create_instances(
  File "/home/miguelflj/.local/lib/python3.10/site-packages/boto3/resources/factory.py", line 581, in do_action
    response = action(self, *args, **kwargs)
  File "/home/miguelflj/.local/lib/python3.10/site-packages/boto3/resources/action.py", line 88, in __call__
    response = getattr(parent.meta.client, operation_name)(*args, **params)
  File "/home/miguelflj/.local/lib/python3.10/site-packages/botocore/client.py", line 565, in _api_call
    return self._make_api_call(operation_name, kwargs)
  File "/home/miguelflj/.local/lib/python3.10/site-packages/botocore/client.py", line 1021, in _make_api_call
    raise error_class(parsed_response, operation_name)
botocore.exceptions.ClientError: An error occurred (Unsupported) when calling the RunInstances operation: The requested configuration is currently not supported. Please check the documentation for supported configurations.
2024-06-14 11:54:28 - ERROR - Error in sa-east-1c: An error occurred (Unsupported) when calling the RunInstances operation: The requested configuration is currently not supported. Please check the documentation for supported configurations.
Traceback (most recent call last):
  File "/home/miguelflj/Documentos/Mestrado/awsbench/awsbench/awsbench.py", line 98, in start_instance
    instances = ec2.create_instances(
  File "/home/miguelflj/.local/lib/python3.10/site-packages/boto3/resources/factory.py", line 581, in do_action
    response = action(self, *args, **kwargs)
  File "/home/miguelflj/.local/lib/python3.10/site-packages/boto3/resources/action.py", line 88, in __call__
    response = getattr(parent.meta.client, operation_name)(*args, **params)
  File "/home/miguelflj/.local/lib/python3.10/site-packages/botocore/client.py", line 565, in _api_call
    return self._make_api_call(operation_name, kwargs)
  File "/home/miguelflj/.local/lib/python3.10/site-packages/botocore/client.py", line 1021, in _make_api_call
    raise error_class(parsed_response, operation_name)
botocore.exceptions.ClientError: An error occurred (Unsupported) when calling the RunInstances operation: The requested configuration is currently not supported. Please check the documentation for supported configurations.
2024-06-14 11:54:29 - ERROR - Error in sa-east-1d: An error occurred (InvalidParameterValue) when calling the RunInstances operation: Invalid availability zone: [sa-east-1d]
Traceback (most recent call last):
  File "/home/miguelflj/Documentos/Mestrado/awsbench/awsbench/awsbench.py", line 98, in start_instance
    instances = ec2.create_instances(
  File "/home/miguelflj/.local/lib/python3.10/site-packages/boto3/resources/factory.py", line 581, in do_action
    response = action(self, *args, **kwargs)
  File "/home/miguelflj/.local/lib/python3.10/site-packages/boto3/resources/action.py", line 88, in __call__
    response = getattr(parent.meta.client, operation_name)(*args, **params)
  File "/home/miguelflj/.local/lib/python3.10/site-packages/botocore/client.py", line 565, in _api_call
    return self._make_api_call(operation_name, kwargs)
  File "/home/miguelflj/.local/lib/python3.10/site-packages/botocore/client.py", line 1021, in _make_api_call
    raise error_class(parsed_response, operation_name)
botocore.exceptions.ClientError: An error occurred (InvalidParameterValue) when calling the RunInstances operation: Invalid availability zone: [sa-east-1d]
2024-06-14 11:54:29 - ERROR - An exception occurred:name 'enchmarkConfig' is not defined
Traceback (most recent call last):
  File "/home/miguelflj/Documentos/Mestrado/awsbench/awsbench/awsbench.py", line 98, in start_instance
    instances = ec2.create_instances(
  File "/home/miguelflj/.local/lib/python3.10/site-packages/boto3/resources/factory.py", line 581, in do_action
    response = action(self, *args, **kwargs)
  File "/home/miguelflj/.local/lib/python3.10/site-packages/boto3/resources/action.py", line 88, in __call__
    response = getattr(parent.meta.client, operation_name)(*args, **params)
  File "/home/miguelflj/.local/lib/python3.10/site-packages/botocore/client.py", line 565, in _api_call
    return self._make_api_call(operation_name, kwargs)
  File "/home/miguelflj/.local/lib/python3.10/site-packages/botocore/client.py", line 1021, in _make_api_call
    raise error_class(parsed_response, operation_name)
botocore.exceptions.ClientError: An error occurred (InvalidParameterValue) when calling the RunInstances operation: Invalid availability zone: [sa-east-1d]

During handling of the above exception, another exception occurred:

Traceback (most recent call last):
  File "/home/miguelflj/Documentos/Mestrado/awsbench/awsbench/awsbench.py", line 196, in benchmark
    instance = start_instance(region, instance_type)
  File "/home/miguelflj/Documentos/Mestrado/awsbench/awsbench/awsbench.py", line 132, in start_instance
    enchmarkConfig.STATUS = 'Error'
NameError: name 'enchmarkConfig' is not defined
2024-06-14 11:54:45 - INFO - Connected (version 2.0, client OpenSSH_9.6p1)
2024-06-14 11:54:46 - INFO - Authentication (publickey) successful!
2024-06-14 11:54:51 - INFO - Connected (version 2.0, client OpenSSH_9.6p1)
2024-06-14 11:54:52 - INFO - Authentication (publickey) successful!
2024-06-14 11:55:21 - INFO - Connected (version 2.0, client OpenSSH_9.6p1)
2024-06-14 11:55:22 - INFO - Authentication (publickey) successful!
2024-06-14 11:55:31 - INFO - Connected (version 2.0, client OpenSSH_9.6p1)
2024-06-14 11:55:31 - INFO - Authentication (publickey) successful!
2024-06-14 11:55:56 - INFO - Connected (version 2.0, client OpenSSH_9.6p1)
2024-06-14 11:55:57 - INFO - Authentication (publickey) successful!
2024-06-14 11:56:10 - INFO - Connected (version 2.0, client OpenSSH_9.6p1)
2024-06-14 11:56:10 - INFO - Authentication (publickey) successful!
2024-06-14 11:56:31 - INFO - Connected (version 2.0, client OpenSSH_9.6p1)
2024-06-14 11:56:32 - INFO - Authentication (publickey) successful!
2024-06-14 11:56:49 - INFO - Connected (version 2.0, client OpenSSH_9.6p1)
2024-06-14 11:56:49 - INFO - Authentication (publickey) successful!
2024-06-14 11:57:07 - INFO - Connected (version 2.0, client OpenSSH_9.6p1)
2024-06-14 11:57:07 - INFO - Authentication (publickey) successful!
2024-06-14 11:57:27 - INFO - Connected (version 2.0, client OpenSSH_9.6p1)
2024-06-14 11:57:28 - INFO - Authentication (publickey) successful!
2024-06-14 11:58:53 - INFO - Connected (version 2.0, client OpenSSH_9.6p1)
2024-06-14 11:58:53 - INFO - Authentication (publickey) successful!
2024-06-14 11:59:17 - INFO - Connected (version 2.0, client OpenSSH_9.6p1)
2024-06-14 11:59:18 - INFO - Authentication (publickey) successful!
2024-06-14 11:59:41 - INFO - Connected (version 2.0, client OpenSSH_9.6p1)
2024-06-14 11:59:42 - INFO - Authentication (publickey) successful!
2024-06-14 11:59:45 - INFO - Connected (version 2.0, client OpenSSH_9.6p1)
2024-06-14 11:59:45 - INFO - Authentication (publickey) successful!
2024-06-14 12:00:05 - INFO - Connected (version 2.0, client OpenSSH_9.6p1)
2024-06-14 12:00:06 - INFO - Authentication (publickey) successful!
2024-06-14 12:00:26 - INFO - Connected (version 2.0, client OpenSSH_9.6p1)
2024-06-14 12:00:26 - INFO - Authentication (publickey) successful!
2024-06-14 12:00:29 - INFO - Connected (version 2.0, client OpenSSH_9.6p1)
2024-06-14 12:00:30 - INFO - Authentication (publickey) successful!
2024-06-14 12:01:06 - INFO - Connected (version 2.0, client OpenSSH_9.6p1)
2024-06-14 12:01:07 - INFO - Authentication (publickey) successful!
2024-06-14 12:01:45 - INFO - Connected (version 2.0, client OpenSSH_9.6p1)
2024-06-14 12:01:46 - INFO - Authentication (publickey) successful!
2024-06-14 12:02:26 - INFO - Connected (version 2.0, client OpenSSH_9.6p1)
2024-06-14 12:02:26 - INFO - Authentication (publickey) successful!
2024-06-14 12:02:35 - INFO - Connected (version 2.0, client OpenSSH_9.6p1)
2024-06-14 12:02:36 - INFO - Authentication (publickey) successful!
2024-06-14 12:03:16 - INFO - Connected (version 2.0, client OpenSSH_9.6p1)
2024-06-14 12:03:17 - INFO - Authentication (publickey) successful!
2024-06-14 12:03:56 - INFO - Connected (version 2.0, client OpenSSH_9.6p1)
2024-06-14 12:03:57 - INFO - Authentication (publickey) successful!
2024-06-14 12:04:30 - INFO - Connected (version 2.0, client OpenSSH_9.6p1)
2024-06-14 12:04:30 - INFO - Authentication (publickey) successful!
2024-06-14 12:04:36 - INFO - Connected (version 2.0, client OpenSSH_9.6p1)
2024-06-14 12:04:37 - INFO - Authentication (publickey) successful!
2024-06-14 12:05:07 - INFO - Connected (version 2.0, client OpenSSH_9.6p1)
2024-06-14 12:05:07 - INFO - Authentication (publickey) successful!
2024-06-14 12:05:16 - INFO - Connected (version 2.0, client OpenSSH_9.6p1)
2024-06-14 12:05:17 - INFO - Authentication (publickey) successful!
2024-06-14 12:05:43 - INFO - Connected (version 2.0, client OpenSSH_9.6p1)
2024-06-14 12:05:43 - INFO - Authentication (publickey) successful!
2024-06-14 12:06:19 - INFO - Connected (version 2.0, client OpenSSH_9.6p1)
2024-06-14 12:06:20 - INFO - Authentication (publickey) successful!
2024-06-14 12:06:56 - INFO - Connected (version 2.0, client OpenSSH_9.6p1)
2024-06-14 12:06:56 - INFO - Authentication (publickey) successful!
2024-06-14 12:07:23 - INFO - Connected (version 2.0, client OpenSSH_9.6p1)
2024-06-14 12:07:23 - INFO - Authentication (publickey) successful!
2024-06-14 12:08:05 - INFO - Connected (version 2.0, client OpenSSH_9.6p1)
2024-06-14 12:08:05 - INFO - Authentication (publickey) successful!
2024-06-14 12:08:26 - INFO - Connected (version 2.0, client OpenSSH_9.6p1)
2024-06-14 12:08:26 - INFO - Authentication (publickey) successful!
2024-06-14 12:08:46 - INFO - Connected (version 2.0, client OpenSSH_9.6p1)
2024-06-14 12:08:47 - INFO - Authentication (publickey) successful!
2024-06-14 12:09:00 - INFO - Connected (version 2.0, client OpenSSH_9.6p1)
2024-06-14 12:09:00 - INFO - Authentication (publickey) successful!
2024-06-14 12:09:28 - INFO - Connected (version 2.0, client OpenSSH_9.6p1)
2024-06-14 12:09:28 - INFO - Authentication (publickey) successful!
2024-06-14 12:09:33 - INFO - Connected (version 2.0, client OpenSSH_9.6p1)
2024-06-14 12:09:33 - INFO - Authentication (publickey) successful!
2024-06-14 12:10:06 - INFO - Connected (version 2.0, client OpenSSH_9.6p1)
2024-06-14 12:10:06 - INFO - Authentication (publickey) successful!
2024-06-14 12:10:09 - INFO - Connected (version 2.0, client OpenSSH_9.6p1)
2024-06-14 12:10:10 - INFO - Authentication (publickey) successful!
2024-06-14 12:10:39 - INFO - Connected (version 2.0, client OpenSSH_9.6p1)
2024-06-14 12:10:39 - INFO - Authentication (publickey) successful!
2024-06-14 12:11:49 - INFO - Connected (version 2.0, client OpenSSH_9.6p1)
2024-06-14 12:11:49 - INFO - Authentication (publickey) successful!
2024-06-14 12:12:05 - INFO - Connected (version 2.0, client OpenSSH_9.6p1)
2024-06-14 12:12:05 - INFO - Authentication (publickey) successful!
2024-06-14 12:12:26 - INFO - Connected (version 2.0, client OpenSSH_9.6p1)
2024-06-14 12:12:26 - INFO - Authentication (publickey) successful!
2024-06-14 12:12:43 - INFO - Connected (version 2.0, client OpenSSH_9.6p1)
2024-06-14 12:12:44 - INFO - Authentication (publickey) successful!
2024-06-14 12:13:02 - INFO - Connected (version 2.0, client OpenSSH_9.6p1)
2024-06-14 12:13:02 - INFO - Authentication (publickey) successful!
2024-06-14 12:13:20 - INFO - Connected (version 2.0, client OpenSSH_9.6p1)
2024-06-14 12:13:20 - INFO - Authentication (publickey) successful!
2024-06-14 12:13:38 - INFO - Connected (version 2.0, client OpenSSH_9.6p1)
2024-06-14 12:13:38 - INFO - Authentication (publickey) successful!
2024-06-14 12:13:56 - INFO - Connected (version 2.0, client OpenSSH_9.6p1)
2024-06-14 12:13:56 - INFO - Authentication (publickey) successful!
2024-06-14 12:14:14 - INFO - Connected (version 2.0, client OpenSSH_9.6p1)
2024-06-14 12:14:14 - INFO - Authentication (publickey) successful!
2024-06-14 12:14:33 - INFO - Connected (version 2.0, client OpenSSH_9.6p1)
2024-06-14 12:14:33 - INFO - Authentication (publickey) successful!
2024-06-14 12:15:48 - ERROR - Error in us-east-1a: An error occurred (InsufficientInstanceCapacity) when calling the RunInstances operation (reached max retries: 4): We currently do not have sufficient c7i.12xlarge capacity in zones with support for 'gp3' volumes. Our system will be working on provisioning additional capacity.
Traceback (most recent call last):
  File "/home/miguelflj/Documentos/Mestrado/awsbench/awsbench/awsbench.py", line 98, in start_instance
    instances = ec2.create_instances(
  File "/home/miguelflj/.local/lib/python3.10/site-packages/boto3/resources/factory.py", line 581, in do_action
    response = action(self, *args, **kwargs)
  File "/home/miguelflj/.local/lib/python3.10/site-packages/boto3/resources/action.py", line 88, in __call__
    response = getattr(parent.meta.client, operation_name)(*args, **params)
  File "/home/miguelflj/.local/lib/python3.10/site-packages/botocore/client.py", line 565, in _api_call
    return self._make_api_call(operation_name, kwargs)
  File "/home/miguelflj/.local/lib/python3.10/site-packages/botocore/client.py", line 1021, in _make_api_call
    raise error_class(parsed_response, operation_name)
botocore.exceptions.ClientError: An error occurred (InsufficientInstanceCapacity) when calling the RunInstances operation (reached max retries: 4): We currently do not have sufficient c7i.12xlarge capacity in zones with support for 'gp3' volumes. Our system will be working on provisioning additional capacity.
2024-06-14 12:16:04 - ERROR - Error in us-east-1b: An error occurred (InsufficientInstanceCapacity) when calling the RunInstances operation (reached max retries: 4): We currently do not have sufficient c7i.12xlarge capacity in zones with support for 'gp3' volumes. Our system will be working on provisioning additional capacity.
Traceback (most recent call last):
  File "/home/miguelflj/Documentos/Mestrado/awsbench/awsbench/awsbench.py", line 98, in start_instance
    instances = ec2.create_instances(
  File "/home/miguelflj/.local/lib/python3.10/site-packages/boto3/resources/factory.py", line 581, in do_action
    response = action(self, *args, **kwargs)
  File "/home/miguelflj/.local/lib/python3.10/site-packages/boto3/resources/action.py", line 88, in __call__
    response = getattr(parent.meta.client, operation_name)(*args, **params)
  File "/home/miguelflj/.local/lib/python3.10/site-packages/botocore/client.py", line 565, in _api_call
    return self._make_api_call(operation_name, kwargs)
  File "/home/miguelflj/.local/lib/python3.10/site-packages/botocore/client.py", line 1021, in _make_api_call
    raise error_class(parsed_response, operation_name)
botocore.exceptions.ClientError: An error occurred (InsufficientInstanceCapacity) when calling the RunInstances operation (reached max retries: 4): We currently do not have sufficient c7i.12xlarge capacity in zones with support for 'gp3' volumes. Our system will be working on provisioning additional capacity.
2024-06-14 12:16:17 - ERROR - Error in us-east-1c: An error occurred (InsufficientInstanceCapacity) when calling the RunInstances operation (reached max retries: 4): We currently do not have sufficient c7i.12xlarge capacity in zones with support for 'gp3' volumes. Our system will be working on provisioning additional capacity.
Traceback (most recent call last):
  File "/home/miguelflj/Documentos/Mestrado/awsbench/awsbench/awsbench.py", line 98, in start_instance
    instances = ec2.create_instances(
  File "/home/miguelflj/.local/lib/python3.10/site-packages/boto3/resources/factory.py", line 581, in do_action
    response = action(self, *args, **kwargs)
  File "/home/miguelflj/.local/lib/python3.10/site-packages/boto3/resources/action.py", line 88, in __call__
    response = getattr(parent.meta.client, operation_name)(*args, **params)
  File "/home/miguelflj/.local/lib/python3.10/site-packages/botocore/client.py", line 565, in _api_call
    return self._make_api_call(operation_name, kwargs)
  File "/home/miguelflj/.local/lib/python3.10/site-packages/botocore/client.py", line 1021, in _make_api_call
    raise error_class(parsed_response, operation_name)
botocore.exceptions.ClientError: An error occurred (InsufficientInstanceCapacity) when calling the RunInstances operation (reached max retries: 4): We currently do not have sufficient c7i.12xlarge capacity in zones with support for 'gp3' volumes. Our system will be working on provisioning additional capacity.
2024-06-14 12:16:27 - ERROR - Error in us-east-1d: An error occurred (InsufficientInstanceCapacity) when calling the RunInstances operation (reached max retries: 4): We currently do not have sufficient c7i.12xlarge capacity in zones with support for 'gp3' volumes. Our system will be working on provisioning additional capacity.
Traceback (most recent call last):
  File "/home/miguelflj/Documentos/Mestrado/awsbench/awsbench/awsbench.py", line 98, in start_instance
    instances = ec2.create_instances(
  File "/home/miguelflj/.local/lib/python3.10/site-packages/boto3/resources/factory.py", line 581, in do_action
    response = action(self, *args, **kwargs)
  File "/home/miguelflj/.local/lib/python3.10/site-packages/boto3/resources/action.py", line 88, in __call__
    response = getattr(parent.meta.client, operation_name)(*args, **params)
  File "/home/miguelflj/.local/lib/python3.10/site-packages/botocore/client.py", line 565, in _api_call
    return self._make_api_call(operation_name, kwargs)
  File "/home/miguelflj/.local/lib/python3.10/site-packages/botocore/client.py", line 1021, in _make_api_call
    raise error_class(parsed_response, operation_name)
botocore.exceptions.ClientError: An error occurred (InsufficientInstanceCapacity) when calling the RunInstances operation (reached max retries: 4): We currently do not have sufficient c7i.12xlarge capacity in zones with support for 'gp3' volumes. Our system will be working on provisioning additional capacity.
2024-06-14 12:16:29 - ERROR - An exception occurred:Max retries reached. Could not create instance.
Traceback (most recent call last):
  File "/home/miguelflj/Documentos/Mestrado/awsbench/awsbench/awsbench.py", line 196, in benchmark
    instance = start_instance(region, instance_type)
  File "/home/miguelflj/Documentos/Mestrado/awsbench/awsbench/awsbench.py", line 138, in start_instance
    raise Exception("Max retries reached. Could not create instance.")
Exception: Max retries reached. Could not create instance.
2024-06-14 12:16:33 - INFO - Connected (version 2.0, client OpenSSH_9.6p1)
2024-06-14 12:16:33 - INFO - Authentication (publickey) successful!
2024-06-14 12:16:53 - INFO - Connected (version 2.0, client OpenSSH_9.6p1)
2024-06-14 12:16:53 - INFO - Authentication (publickey) successful!
2024-06-14 12:17:03 - INFO - Connected (version 2.0, client OpenSSH_9.6p1)
2024-06-14 12:17:03 - INFO - Authentication (publickey) successful!
2024-06-14 12:17:31 - INFO - Connected (version 2.0, client OpenSSH_9.6p1)
2024-06-14 12:17:32 - INFO - Authentication (publickey) successful!
2024-06-14 12:17:33 - INFO - Connected (version 2.0, client OpenSSH_9.6p1)
2024-06-14 12:17:33 - INFO - Authentication (publickey) successful!
2024-06-14 12:18:02 - INFO - Connected (version 2.0, client OpenSSH_9.6p1)
2024-06-14 12:18:02 - INFO - Authentication (publickey) successful!
2024-06-14 12:18:09 - INFO - Connected (version 2.0, client OpenSSH_9.6p1)
2024-06-14 12:18:10 - INFO - Authentication (publickey) successful!
2024-06-14 12:18:31 - INFO - Connected (version 2.0, client OpenSSH_9.6p1)
2024-06-14 12:18:31 - INFO - Authentication (publickey) successful!
2024-06-14 12:18:47 - INFO - Connected (version 2.0, client OpenSSH_9.6p1)
2024-06-14 12:18:47 - INFO - Authentication (publickey) successful!
2024-06-14 12:19:24 - INFO - Connected (version 2.0, client OpenSSH_9.6p1)
2024-06-14 12:19:25 - INFO - Authentication (publickey) successful!
2024-06-14 12:20:54 - INFO - Connected (version 2.0, client OpenSSH_9.6p1)
2024-06-14 12:20:54 - INFO - Authentication (publickey) successful!
2024-06-14 12:21:25 - INFO - Connected (version 2.0, client OpenSSH_9.6p1)
2024-06-14 12:21:25 - INFO - Authentication (publickey) successful!
2024-06-14 12:21:28 - INFO - Connected (version 2.0, client OpenSSH_9.6p1)
2024-06-14 12:21:29 - INFO - Authentication (publickey) successful!
2024-06-14 12:21:54 - INFO - Connected (version 2.0, client OpenSSH_9.6p1)
2024-06-14 12:21:54 - INFO - Authentication (publickey) successful!
2024-06-14 12:21:59 - INFO - Connected (version 2.0, client OpenSSH_9.6p1)
2024-06-14 12:21:59 - INFO - Authentication (publickey) successful!
2024-06-14 12:22:23 - INFO - Connected (version 2.0, client OpenSSH_9.6p1)
2024-06-14 12:22:23 - INFO - Authentication (publickey) successful!
2024-06-14 12:22:27 - INFO - Connected (version 2.0, client OpenSSH_9.6p1)
2024-06-14 12:22:28 - INFO - Authentication (publickey) successful!
2024-06-14 12:22:53 - INFO - Connected (version 2.0, client OpenSSH_9.6p1)
2024-06-14 12:22:53 - INFO - Authentication (publickey) successful!
2024-06-14 12:22:56 - INFO - Connected (version 2.0, client OpenSSH_9.6p1)
2024-06-14 12:22:57 - INFO - Authentication (publickey) successful!
2024-06-14 12:23:26 - INFO - Connected (version 2.0, client OpenSSH_9.6p1)
2024-06-14 12:23:27 - INFO - Authentication (publickey) successful!
2024-06-14 12:24:09 - ERROR - Error getting price for c7a.16xlarge
Traceback (most recent call last):
  File "/home/miguelflj/Documentos/Mestrado/awsbench/awsbench/awsbench.py", line 189, in benchmark
    ondemand_price = aws.get_price_ondemand(region, instance_type)
  File "/home/miguelflj/Documentos/Mestrado/awsbench/awsbench/aws_bench/pricing_handler.py", line 26, in get_price_ondemand
    od = json.loads(data['PriceList'][0])['terms']['OnDemand']
IndexError: list index out of range
2024-06-14 12:24:10 - ERROR - Error in sa-east-1a: An error occurred (Unsupported) when calling the RunInstances operation: The requested configuration is currently not supported. Please check the documentation for supported configurations.
Traceback (most recent call last):
  File "/home/miguelflj/Documentos/Mestrado/awsbench/awsbench/awsbench.py", line 98, in start_instance
    instances = ec2.create_instances(
  File "/home/miguelflj/.local/lib/python3.10/site-packages/boto3/resources/factory.py", line 581, in do_action
    response = action(self, *args, **kwargs)
  File "/home/miguelflj/.local/lib/python3.10/site-packages/boto3/resources/action.py", line 88, in __call__
    response = getattr(parent.meta.client, operation_name)(*args, **params)
  File "/home/miguelflj/.local/lib/python3.10/site-packages/botocore/client.py", line 565, in _api_call
    return self._make_api_call(operation_name, kwargs)
  File "/home/miguelflj/.local/lib/python3.10/site-packages/botocore/client.py", line 1021, in _make_api_call
    raise error_class(parsed_response, operation_name)
botocore.exceptions.ClientError: An error occurred (Unsupported) when calling the RunInstances operation: The requested configuration is currently not supported. Please check the documentation for supported configurations.
2024-06-14 12:24:10 - ERROR - Error in sa-east-1b: An error occurred (Unsupported) when calling the RunInstances operation: The requested configuration is currently not supported. Please check the documentation for supported configurations.
Traceback (most recent call last):
  File "/home/miguelflj/Documentos/Mestrado/awsbench/awsbench/awsbench.py", line 98, in start_instance
    instances = ec2.create_instances(
  File "/home/miguelflj/.local/lib/python3.10/site-packages/boto3/resources/factory.py", line 581, in do_action
    response = action(self, *args, **kwargs)
  File "/home/miguelflj/.local/lib/python3.10/site-packages/boto3/resources/action.py", line 88, in __call__
    response = getattr(parent.meta.client, operation_name)(*args, **params)
  File "/home/miguelflj/.local/lib/python3.10/site-packages/botocore/client.py", line 565, in _api_call
    return self._make_api_call(operation_name, kwargs)
  File "/home/miguelflj/.local/lib/python3.10/site-packages/botocore/client.py", line 1021, in _make_api_call
    raise error_class(parsed_response, operation_name)
botocore.exceptions.ClientError: An error occurred (Unsupported) when calling the RunInstances operation: The requested configuration is currently not supported. Please check the documentation for supported configurations.
2024-06-14 12:24:11 - ERROR - Error in sa-east-1c: An error occurred (Unsupported) when calling the RunInstances operation: The requested configuration is currently not supported. Please check the documentation for supported configurations.
Traceback (most recent call last):
  File "/home/miguelflj/Documentos/Mestrado/awsbench/awsbench/awsbench.py", line 98, in start_instance
    instances = ec2.create_instances(
  File "/home/miguelflj/.local/lib/python3.10/site-packages/boto3/resources/factory.py", line 581, in do_action
    response = action(self, *args, **kwargs)
  File "/home/miguelflj/.local/lib/python3.10/site-packages/boto3/resources/action.py", line 88, in __call__
    response = getattr(parent.meta.client, operation_name)(*args, **params)
  File "/home/miguelflj/.local/lib/python3.10/site-packages/botocore/client.py", line 565, in _api_call
    return self._make_api_call(operation_name, kwargs)
  File "/home/miguelflj/.local/lib/python3.10/site-packages/botocore/client.py", line 1021, in _make_api_call
    raise error_class(parsed_response, operation_name)
botocore.exceptions.ClientError: An error occurred (Unsupported) when calling the RunInstances operation: The requested configuration is currently not supported. Please check the documentation for supported configurations.
2024-06-14 12:24:11 - ERROR - Error in sa-east-1d: An error occurred (InvalidParameterValue) when calling the RunInstances operation: Invalid availability zone: [sa-east-1d]
Traceback (most recent call last):
  File "/home/miguelflj/Documentos/Mestrado/awsbench/awsbench/awsbench.py", line 98, in start_instance
    instances = ec2.create_instances(
  File "/home/miguelflj/.local/lib/python3.10/site-packages/boto3/resources/factory.py", line 581, in do_action
    response = action(self, *args, **kwargs)
  File "/home/miguelflj/.local/lib/python3.10/site-packages/boto3/resources/action.py", line 88, in __call__
    response = getattr(parent.meta.client, operation_name)(*args, **params)
  File "/home/miguelflj/.local/lib/python3.10/site-packages/botocore/client.py", line 565, in _api_call
    return self._make_api_call(operation_name, kwargs)
  File "/home/miguelflj/.local/lib/python3.10/site-packages/botocore/client.py", line 1021, in _make_api_call
    raise error_class(parsed_response, operation_name)
botocore.exceptions.ClientError: An error occurred (InvalidParameterValue) when calling the RunInstances operation: Invalid availability zone: [sa-east-1d]
2024-06-14 12:24:11 - ERROR - An exception occurred:name 'enchmarkConfig' is not defined
Traceback (most recent call last):
  File "/home/miguelflj/Documentos/Mestrado/awsbench/awsbench/awsbench.py", line 98, in start_instance
    instances = ec2.create_instances(
  File "/home/miguelflj/.local/lib/python3.10/site-packages/boto3/resources/factory.py", line 581, in do_action
    response = action(self, *args, **kwargs)
  File "/home/miguelflj/.local/lib/python3.10/site-packages/boto3/resources/action.py", line 88, in __call__
    response = getattr(parent.meta.client, operation_name)(*args, **params)
  File "/home/miguelflj/.local/lib/python3.10/site-packages/botocore/client.py", line 565, in _api_call
    return self._make_api_call(operation_name, kwargs)
  File "/home/miguelflj/.local/lib/python3.10/site-packages/botocore/client.py", line 1021, in _make_api_call
    raise error_class(parsed_response, operation_name)
botocore.exceptions.ClientError: An error occurred (InvalidParameterValue) when calling the RunInstances operation: Invalid availability zone: [sa-east-1d]

During handling of the above exception, another exception occurred:

Traceback (most recent call last):
  File "/home/miguelflj/Documentos/Mestrado/awsbench/awsbench/awsbench.py", line 196, in benchmark
    instance = start_instance(region, instance_type)
  File "/home/miguelflj/Documentos/Mestrado/awsbench/awsbench/awsbench.py", line 132, in start_instance
    enchmarkConfig.STATUS = 'Error'
NameError: name 'enchmarkConfig' is not defined
2024-06-14 12:24:34 - INFO - Connected (version 2.0, client OpenSSH_9.6p1)
2024-06-14 12:24:34 - INFO - Authentication (publickey) successful!
2024-06-14 12:24:58 - INFO - Connected (version 2.0, client OpenSSH_9.6p1)
2024-06-14 12:24:58 - INFO - Authentication (publickey) successful!
2024-06-14 12:25:23 - INFO - Connected (version 2.0, client OpenSSH_9.6p1)
2024-06-14 12:25:23 - INFO - Authentication (publickey) successful!
2024-06-14 12:25:48 - INFO - Connected (version 2.0, client OpenSSH_9.6p1)
2024-06-14 12:25:48 - INFO - Authentication (publickey) successful!
2024-06-14 12:25:51 - INFO - Connected (version 2.0, client OpenSSH_9.6p1)
2024-06-14 12:25:52 - INFO - Authentication (publickey) successful!
2024-06-14 12:26:13 - INFO - Connected (version 2.0, client OpenSSH_9.6p1)
2024-06-14 12:26:13 - INFO - Authentication (publickey) successful!
2024-06-14 12:26:23 - INFO - Connected (version 2.0, client OpenSSH_9.6p1)
2024-06-14 12:26:24 - INFO - Authentication (publickey) successful!
2024-06-14 12:26:53 - INFO - Connected (version 2.0, client OpenSSH_9.6p1)
2024-06-14 12:26:54 - INFO - Authentication (publickey) successful!
2024-06-14 12:27:24 - INFO - Connected (version 2.0, client OpenSSH_9.6p1)
2024-06-14 12:27:24 - INFO - Authentication (publickey) successful!
2024-06-14 12:27:54 - INFO - Connected (version 2.0, client OpenSSH_9.6p1)
2024-06-14 12:27:55 - INFO - Authentication (publickey) successful!
2024-06-14 12:28:17 - INFO - Connected (version 2.0, client OpenSSH_9.6p1)
2024-06-14 12:28:17 - INFO - Authentication (publickey) successful!
2024-06-14 12:28:44 - INFO - Connected (version 2.0, client OpenSSH_9.6p1)
2024-06-14 12:28:45 - INFO - Authentication (publickey) successful!
2024-06-14 12:29:11 - INFO - Connected (version 2.0, client OpenSSH_9.6p1)
2024-06-14 12:29:11 - INFO - Authentication (publickey) successful!
2024-06-14 12:29:27 - ERROR - Error in us-east-1a: An error occurred (InsufficientInstanceCapacity) when calling the RunInstances operation (reached max retries: 4): We currently do not have sufficient c7a.16xlarge capacity in zones with support for 'gp3' volumes. Our system will be working on provisioning additional capacity.
Traceback (most recent call last):
  File "/home/miguelflj/Documentos/Mestrado/awsbench/awsbench/awsbench.py", line 98, in start_instance
    instances = ec2.create_instances(
  File "/home/miguelflj/.local/lib/python3.10/site-packages/boto3/resources/factory.py", line 581, in do_action
    response = action(self, *args, **kwargs)
  File "/home/miguelflj/.local/lib/python3.10/site-packages/boto3/resources/action.py", line 88, in __call__
    response = getattr(parent.meta.client, operation_name)(*args, **params)
  File "/home/miguelflj/.local/lib/python3.10/site-packages/botocore/client.py", line 565, in _api_call
    return self._make_api_call(operation_name, kwargs)
  File "/home/miguelflj/.local/lib/python3.10/site-packages/botocore/client.py", line 1021, in _make_api_call
    raise error_class(parsed_response, operation_name)
botocore.exceptions.ClientError: An error occurred (InsufficientInstanceCapacity) when calling the RunInstances operation (reached max retries: 4): We currently do not have sufficient c7a.16xlarge capacity in zones with support for 'gp3' volumes. Our system will be working on provisioning additional capacity.
2024-06-14 12:29:37 - ERROR - Error in us-east-1b: An error occurred (InsufficientInstanceCapacity) when calling the RunInstances operation (reached max retries: 4): We currently do not have sufficient c7a.16xlarge capacity in zones with support for 'gp3' volumes. Our system will be working on provisioning additional capacity.
Traceback (most recent call last):
  File "/home/miguelflj/Documentos/Mestrado/awsbench/awsbench/awsbench.py", line 98, in start_instance
    instances = ec2.create_instances(
  File "/home/miguelflj/.local/lib/python3.10/site-packages/boto3/resources/factory.py", line 581, in do_action
    response = action(self, *args, **kwargs)
  File "/home/miguelflj/.local/lib/python3.10/site-packages/boto3/resources/action.py", line 88, in __call__
    response = getattr(parent.meta.client, operation_name)(*args, **params)
  File "/home/miguelflj/.local/lib/python3.10/site-packages/botocore/client.py", line 565, in _api_call
    return self._make_api_call(operation_name, kwargs)
  File "/home/miguelflj/.local/lib/python3.10/site-packages/botocore/client.py", line 1021, in _make_api_call
    raise error_class(parsed_response, operation_name)
botocore.exceptions.ClientError: An error occurred (InsufficientInstanceCapacity) when calling the RunInstances operation (reached max retries: 4): We currently do not have sufficient c7a.16xlarge capacity in zones with support for 'gp3' volumes. Our system will be working on provisioning additional capacity.
2024-06-14 12:29:37 - INFO - Connected (version 2.0, client OpenSSH_9.6p1)
2024-06-14 12:29:37 - INFO - Authentication (publickey) successful!
2024-06-14 12:29:51 - ERROR - Error in us-east-1c: An error occurred (InsufficientInstanceCapacity) when calling the RunInstances operation (reached max retries: 4): We currently do not have sufficient c7a.16xlarge capacity in zones with support for 'gp3' volumes. Our system will be working on provisioning additional capacity.
Traceback (most recent call last):
  File "/home/miguelflj/Documentos/Mestrado/awsbench/awsbench/awsbench.py", line 98, in start_instance
    instances = ec2.create_instances(
  File "/home/miguelflj/.local/lib/python3.10/site-packages/boto3/resources/factory.py", line 581, in do_action
    response = action(self, *args, **kwargs)
  File "/home/miguelflj/.local/lib/python3.10/site-packages/boto3/resources/action.py", line 88, in __call__
    response = getattr(parent.meta.client, operation_name)(*args, **params)
  File "/home/miguelflj/.local/lib/python3.10/site-packages/botocore/client.py", line 565, in _api_call
    return self._make_api_call(operation_name, kwargs)
  File "/home/miguelflj/.local/lib/python3.10/site-packages/botocore/client.py", line 1021, in _make_api_call
    raise error_class(parsed_response, operation_name)
botocore.exceptions.ClientError: An error occurred (InsufficientInstanceCapacity) when calling the RunInstances operation (reached max retries: 4): We currently do not have sufficient c7a.16xlarge capacity in zones with support for 'gp3' volumes. Our system will be working on provisioning additional capacity.
2024-06-14 12:30:03 - INFO - Connected (version 2.0, client OpenSSH_9.6p1)
2024-06-14 12:30:03 - INFO - Authentication (publickey) successful!
2024-06-14 12:30:14 - INFO - Connected (version 2.0, client OpenSSH_9.6p1)
2024-06-14 12:30:15 - INFO - Authentication (publickey) successful!
2024-06-14 12:30:41 - INFO - Connected (version 2.0, client OpenSSH_9.6p1)
2024-06-14 12:30:42 - INFO - Authentication (publickey) successful!
2024-06-14 12:31:08 - INFO - Connected (version 2.0, client OpenSSH_9.6p1)
2024-06-14 12:31:08 - INFO - Authentication (publickey) successful!
2024-06-14 12:31:34 - INFO - Connected (version 2.0, client OpenSSH_9.6p1)
2024-06-14 12:31:35 - INFO - Authentication (publickey) successful!
2024-06-14 12:32:01 - INFO - Connected (version 2.0, client OpenSSH_9.6p1)
2024-06-14 12:32:01 - INFO - Authentication (publickey) successful!
2024-06-14 12:34:16 - ERROR - Error in us-east-1a: An error occurred (InsufficientInstanceCapacity) when calling the RunInstances operation (reached max retries: 4): We currently do not have sufficient c7i.16xlarge capacity in zones with support for 'gp3' volumes. Our system will be working on provisioning additional capacity.
Traceback (most recent call last):
  File "/home/miguelflj/Documentos/Mestrado/awsbench/awsbench/awsbench.py", line 98, in start_instance
    instances = ec2.create_instances(
  File "/home/miguelflj/.local/lib/python3.10/site-packages/boto3/resources/factory.py", line 581, in do_action
    response = action(self, *args, **kwargs)
  File "/home/miguelflj/.local/lib/python3.10/site-packages/boto3/resources/action.py", line 88, in __call__
    response = getattr(parent.meta.client, operation_name)(*args, **params)
  File "/home/miguelflj/.local/lib/python3.10/site-packages/botocore/client.py", line 565, in _api_call
    return self._make_api_call(operation_name, kwargs)
  File "/home/miguelflj/.local/lib/python3.10/site-packages/botocore/client.py", line 1021, in _make_api_call
    raise error_class(parsed_response, operation_name)
botocore.exceptions.ClientError: An error occurred (InsufficientInstanceCapacity) when calling the RunInstances operation (reached max retries: 4): We currently do not have sufficient c7i.16xlarge capacity in zones with support for 'gp3' volumes. Our system will be working on provisioning additional capacity.
2024-06-14 12:34:32 - ERROR - Error in us-east-1b: An error occurred (InsufficientInstanceCapacity) when calling the RunInstances operation (reached max retries: 4): We currently do not have sufficient c7i.16xlarge capacity in zones with support for 'gp3' volumes. Our system will be working on provisioning additional capacity.
Traceback (most recent call last):
  File "/home/miguelflj/Documentos/Mestrado/awsbench/awsbench/awsbench.py", line 98, in start_instance
    instances = ec2.create_instances(
  File "/home/miguelflj/.local/lib/python3.10/site-packages/boto3/resources/factory.py", line 581, in do_action
    response = action(self, *args, **kwargs)
  File "/home/miguelflj/.local/lib/python3.10/site-packages/boto3/resources/action.py", line 88, in __call__
    response = getattr(parent.meta.client, operation_name)(*args, **params)
  File "/home/miguelflj/.local/lib/python3.10/site-packages/botocore/client.py", line 565, in _api_call
    return self._make_api_call(operation_name, kwargs)
  File "/home/miguelflj/.local/lib/python3.10/site-packages/botocore/client.py", line 1021, in _make_api_call
    raise error_class(parsed_response, operation_name)
botocore.exceptions.ClientError: An error occurred (InsufficientInstanceCapacity) when calling the RunInstances operation (reached max retries: 4): We currently do not have sufficient c7i.16xlarge capacity in zones with support for 'gp3' volumes. Our system will be working on provisioning additional capacity.
2024-06-14 12:34:50 - ERROR - Error in us-east-1c: An error occurred (InsufficientInstanceCapacity) when calling the RunInstances operation (reached max retries: 4): We currently do not have sufficient c7i.16xlarge capacity in zones with support for 'gp3' volumes. Our system will be working on provisioning additional capacity.
Traceback (most recent call last):
  File "/home/miguelflj/Documentos/Mestrado/awsbench/awsbench/awsbench.py", line 98, in start_instance
    instances = ec2.create_instances(
  File "/home/miguelflj/.local/lib/python3.10/site-packages/boto3/resources/factory.py", line 581, in do_action
    response = action(self, *args, **kwargs)
  File "/home/miguelflj/.local/lib/python3.10/site-packages/boto3/resources/action.py", line 88, in __call__
    response = getattr(parent.meta.client, operation_name)(*args, **params)
  File "/home/miguelflj/.local/lib/python3.10/site-packages/botocore/client.py", line 565, in _api_call
    return self._make_api_call(operation_name, kwargs)
  File "/home/miguelflj/.local/lib/python3.10/site-packages/botocore/client.py", line 1021, in _make_api_call
    raise error_class(parsed_response, operation_name)
botocore.exceptions.ClientError: An error occurred (InsufficientInstanceCapacity) when calling the RunInstances operation (reached max retries: 4): We currently do not have sufficient c7i.16xlarge capacity in zones with support for 'gp3' volumes. Our system will be working on provisioning additional capacity.
2024-06-14 12:35:03 - ERROR - Error in us-east-1d: An error occurred (InsufficientInstanceCapacity) when calling the RunInstances operation (reached max retries: 4): We currently do not have sufficient c7i.16xlarge capacity in zones with support for 'gp3' volumes. Our system will be working on provisioning additional capacity.
Traceback (most recent call last):
  File "/home/miguelflj/Documentos/Mestrado/awsbench/awsbench/awsbench.py", line 98, in start_instance
    instances = ec2.create_instances(
  File "/home/miguelflj/.local/lib/python3.10/site-packages/boto3/resources/factory.py", line 581, in do_action
    response = action(self, *args, **kwargs)
  File "/home/miguelflj/.local/lib/python3.10/site-packages/boto3/resources/action.py", line 88, in __call__
    response = getattr(parent.meta.client, operation_name)(*args, **params)
  File "/home/miguelflj/.local/lib/python3.10/site-packages/botocore/client.py", line 565, in _api_call
    return self._make_api_call(operation_name, kwargs)
  File "/home/miguelflj/.local/lib/python3.10/site-packages/botocore/client.py", line 1021, in _make_api_call
    raise error_class(parsed_response, operation_name)
botocore.exceptions.ClientError: An error occurred (InsufficientInstanceCapacity) when calling the RunInstances operation (reached max retries: 4): We currently do not have sufficient c7i.16xlarge capacity in zones with support for 'gp3' volumes. Our system will be working on provisioning additional capacity.
2024-06-14 12:35:05 - ERROR - An exception occurred:Max retries reached. Could not create instance.
Traceback (most recent call last):
  File "/home/miguelflj/Documentos/Mestrado/awsbench/awsbench/awsbench.py", line 196, in benchmark
    instance = start_instance(region, instance_type)
  File "/home/miguelflj/Documentos/Mestrado/awsbench/awsbench/awsbench.py", line 138, in start_instance
    raise Exception("Max retries reached. Could not create instance.")
Exception: Max retries reached. Could not create instance.
2024-06-14 12:35:29 - INFO - Connected (version 2.0, client OpenSSH_9.6p1)
2024-06-14 12:35:30 - INFO - Authentication (publickey) successful!
2024-06-14 12:35:58 - INFO - Connected (version 2.0, client OpenSSH_9.6p1)
2024-06-14 12:35:59 - INFO - Authentication (publickey) successful!
2024-06-14 12:36:25 - INFO - Connected (version 2.0, client OpenSSH_9.6p1)
2024-06-14 12:36:26 - INFO - Authentication (publickey) successful!
2024-06-14 12:36:53 - INFO - Connected (version 2.0, client OpenSSH_9.6p1)
2024-06-14 12:36:54 - INFO - Authentication (publickey) successful!
2024-06-14 12:37:20 - INFO - Connected (version 2.0, client OpenSSH_9.6p1)
2024-06-14 12:37:21 - INFO - Authentication (publickey) successful!
2024-06-14 13:06:15 - INFO - Start execution in us-east-1 N=5 JsonFile=instance_info.json
2024-06-14 13:06:15 - INFO - Start execution in sa-east-1 N=5 JsonFile=instance_info.json
2024-06-14 13:06:16 - ERROR - Error getting price for c7a.12xlarge
Traceback (most recent call last):
  File "/home/miguelflj/Documentos/Mestrado/awsbench/awsbench/awsbench.py", line 189, in benchmark
    ondemand_price = aws.get_price_ondemand(region, instance_type)
  File "/home/miguelflj/Documentos/Mestrado/awsbench/awsbench/aws_bench/pricing_handler.py", line 26, in get_price_ondemand
    od = json.loads(data['PriceList'][0])['terms']['OnDemand']
IndexError: list index out of range
2024-06-14 13:06:17 - ERROR - Error in sa-east-1a: An error occurred (Unsupported) when calling the RunInstances operation: The requested configuration is currently not supported. Please check the documentation for supported configurations.
Traceback (most recent call last):
  File "/home/miguelflj/Documentos/Mestrado/awsbench/awsbench/awsbench.py", line 98, in start_instance
    instances = ec2.create_instances(
  File "/home/miguelflj/.local/lib/python3.10/site-packages/boto3/resources/factory.py", line 581, in do_action
    response = action(self, *args, **kwargs)
  File "/home/miguelflj/.local/lib/python3.10/site-packages/boto3/resources/action.py", line 88, in __call__
    response = getattr(parent.meta.client, operation_name)(*args, **params)
  File "/home/miguelflj/.local/lib/python3.10/site-packages/botocore/client.py", line 565, in _api_call
    return self._make_api_call(operation_name, kwargs)
  File "/home/miguelflj/.local/lib/python3.10/site-packages/botocore/client.py", line 1021, in _make_api_call
    raise error_class(parsed_response, operation_name)
botocore.exceptions.ClientError: An error occurred (Unsupported) when calling the RunInstances operation: The requested configuration is currently not supported. Please check the documentation for supported configurations.
2024-06-14 13:06:17 - ERROR - Error in sa-east-1b: An error occurred (Unsupported) when calling the RunInstances operation: The requested configuration is currently not supported. Please check the documentation for supported configurations.
Traceback (most recent call last):
  File "/home/miguelflj/Documentos/Mestrado/awsbench/awsbench/awsbench.py", line 98, in start_instance
    instances = ec2.create_instances(
  File "/home/miguelflj/.local/lib/python3.10/site-packages/boto3/resources/factory.py", line 581, in do_action
    response = action(self, *args, **kwargs)
  File "/home/miguelflj/.local/lib/python3.10/site-packages/boto3/resources/action.py", line 88, in __call__
    response = getattr(parent.meta.client, operation_name)(*args, **params)
  File "/home/miguelflj/.local/lib/python3.10/site-packages/botocore/client.py", line 565, in _api_call
    return self._make_api_call(operation_name, kwargs)
  File "/home/miguelflj/.local/lib/python3.10/site-packages/botocore/client.py", line 1021, in _make_api_call
    raise error_class(parsed_response, operation_name)
botocore.exceptions.ClientError: An error occurred (Unsupported) when calling the RunInstances operation: The requested configuration is currently not supported. Please check the documentation for supported configurations.
2024-06-14 13:06:18 - ERROR - Error in sa-east-1c: An error occurred (Unsupported) when calling the RunInstances operation: The requested configuration is currently not supported. Please check the documentation for supported configurations.
Traceback (most recent call last):
  File "/home/miguelflj/Documentos/Mestrado/awsbench/awsbench/awsbench.py", line 98, in start_instance
    instances = ec2.create_instances(
  File "/home/miguelflj/.local/lib/python3.10/site-packages/boto3/resources/factory.py", line 581, in do_action
    response = action(self, *args, **kwargs)
  File "/home/miguelflj/.local/lib/python3.10/site-packages/boto3/resources/action.py", line 88, in __call__
    response = getattr(parent.meta.client, operation_name)(*args, **params)
  File "/home/miguelflj/.local/lib/python3.10/site-packages/botocore/client.py", line 565, in _api_call
    return self._make_api_call(operation_name, kwargs)
  File "/home/miguelflj/.local/lib/python3.10/site-packages/botocore/client.py", line 1021, in _make_api_call
    raise error_class(parsed_response, operation_name)
botocore.exceptions.ClientError: An error occurred (Unsupported) when calling the RunInstances operation: The requested configuration is currently not supported. Please check the documentation for supported configurations.
2024-06-14 13:06:34 - ERROR - An exception occurred:Max retries reached. Could not create instance.
Traceback (most recent call last):
  File "/home/miguelflj/Documentos/Mestrado/awsbench/awsbench/awsbench.py", line 196, in benchmark
    instance = start_instance(region, instance_type)
  File "/home/miguelflj/Documentos/Mestrado/awsbench/awsbench/awsbench.py", line 138, in start_instance
    raise Exception("Max retries reached. Could not create instance.")
Exception: Max retries reached. Could not create instance.
2024-06-14 13:06:36 - ERROR - Error in us-east-1a: An error occurred (InsufficientInstanceCapacity) when calling the RunInstances operation (reached max retries: 4): We currently do not have sufficient c7a.12xlarge capacity in zones with support for 'gp3' volumes. Our system will be working on provisioning additional capacity.
Traceback (most recent call last):
  File "/home/miguelflj/Documentos/Mestrado/awsbench/awsbench/awsbench.py", line 98, in start_instance
    instances = ec2.create_instances(
  File "/home/miguelflj/.local/lib/python3.10/site-packages/boto3/resources/factory.py", line 581, in do_action
    response = action(self, *args, **kwargs)
  File "/home/miguelflj/.local/lib/python3.10/site-packages/boto3/resources/action.py", line 88, in __call__
    response = getattr(parent.meta.client, operation_name)(*args, **params)
  File "/home/miguelflj/.local/lib/python3.10/site-packages/botocore/client.py", line 565, in _api_call
    return self._make_api_call(operation_name, kwargs)
  File "/home/miguelflj/.local/lib/python3.10/site-packages/botocore/client.py", line 1021, in _make_api_call
    raise error_class(parsed_response, operation_name)
botocore.exceptions.ClientError: An error occurred (InsufficientInstanceCapacity) when calling the RunInstances operation (reached max retries: 4): We currently do not have sufficient c7a.12xlarge capacity in zones with support for 'gp3' volumes. Our system will be working on provisioning additional capacity.
2024-06-14 13:06:45 - ERROR - Error in us-east-1b: An error occurred (InsufficientInstanceCapacity) when calling the RunInstances operation (reached max retries: 4): We currently do not have sufficient c7a.12xlarge capacity in zones with support for 'gp3' volumes. Our system will be working on provisioning additional capacity.
Traceback (most recent call last):
  File "/home/miguelflj/Documentos/Mestrado/awsbench/awsbench/awsbench.py", line 98, in start_instance
    instances = ec2.create_instances(
  File "/home/miguelflj/.local/lib/python3.10/site-packages/boto3/resources/factory.py", line 581, in do_action
    response = action(self, *args, **kwargs)
  File "/home/miguelflj/.local/lib/python3.10/site-packages/boto3/resources/action.py", line 88, in __call__
    response = getattr(parent.meta.client, operation_name)(*args, **params)
  File "/home/miguelflj/.local/lib/python3.10/site-packages/botocore/client.py", line 565, in _api_call
    return self._make_api_call(operation_name, kwargs)
  File "/home/miguelflj/.local/lib/python3.10/site-packages/botocore/client.py", line 1021, in _make_api_call
    raise error_class(parsed_response, operation_name)
botocore.exceptions.ClientError: An error occurred (InsufficientInstanceCapacity) when calling the RunInstances operation (reached max retries: 4): We currently do not have sufficient c7a.12xlarge capacity in zones with support for 'gp3' volumes. Our system will be working on provisioning additional capacity.
2024-06-14 13:06:56 - INFO - Connected (version 2.0, client OpenSSH_9.6p1)
2024-06-14 13:06:56 - INFO - Authentication (publickey) successful!
2024-06-14 13:06:58 - ERROR - Error in us-east-1c: An error occurred (InsufficientInstanceCapacity) when calling the RunInstances operation (reached max retries: 4): We currently do not have sufficient c7a.12xlarge capacity in zones with support for 'gp3' volumes. Our system will be working on provisioning additional capacity.
Traceback (most recent call last):
  File "/home/miguelflj/Documentos/Mestrado/awsbench/awsbench/awsbench.py", line 98, in start_instance
    instances = ec2.create_instances(
  File "/home/miguelflj/.local/lib/python3.10/site-packages/boto3/resources/factory.py", line 581, in do_action
    response = action(self, *args, **kwargs)
  File "/home/miguelflj/.local/lib/python3.10/site-packages/boto3/resources/action.py", line 88, in __call__
    response = getattr(parent.meta.client, operation_name)(*args, **params)
  File "/home/miguelflj/.local/lib/python3.10/site-packages/botocore/client.py", line 565, in _api_call
    return self._make_api_call(operation_name, kwargs)
  File "/home/miguelflj/.local/lib/python3.10/site-packages/botocore/client.py", line 1021, in _make_api_call
    raise error_class(parsed_response, operation_name)
botocore.exceptions.ClientError: An error occurred (InsufficientInstanceCapacity) when calling the RunInstances operation (reached max retries: 4): We currently do not have sufficient c7a.12xlarge capacity in zones with support for 'gp3' volumes. Our system will be working on provisioning additional capacity.
2024-06-14 13:07:00 - ERROR - An exception occurred:Max retries reached. Could not create instance.
Traceback (most recent call last):
  File "/home/miguelflj/Documentos/Mestrado/awsbench/awsbench/awsbench.py", line 196, in benchmark
    instance = start_instance(region, instance_type)
  File "/home/miguelflj/Documentos/Mestrado/awsbench/awsbench/awsbench.py", line 138, in start_instance
    raise Exception("Max retries reached. Could not create instance.")
Exception: Max retries reached. Could not create instance.
2024-06-14 13:07:23 - INFO - Connected (version 2.0, client OpenSSH_9.6p1)
2024-06-14 13:07:24 - INFO - Authentication (publickey) successful!
2024-06-14 13:07:31 - INFO - Connected (version 2.0, client OpenSSH_9.6p1)
2024-06-14 13:07:31 - INFO - Authentication (publickey) successful!
2024-06-14 13:07:59 - INFO - Connected (version 2.0, client OpenSSH_9.6p1)
2024-06-14 13:08:00 - INFO - Authentication (publickey) successful!
2024-06-14 13:08:05 - INFO - Connected (version 2.0, client OpenSSH_9.6p1)
2024-06-14 13:08:05 - INFO - Authentication (publickey) successful!
2024-06-14 13:08:34 - INFO - Connected (version 2.0, client OpenSSH_9.6p1)
2024-06-14 13:08:35 - INFO - Authentication (publickey) successful!
2024-06-14 13:08:39 - INFO - Connected (version 2.0, client OpenSSH_9.6p1)
2024-06-14 13:08:39 - INFO - Authentication (publickey) successful!
2024-06-14 13:09:09 - INFO - Connected (version 2.0, client OpenSSH_9.6p1)
2024-06-14 13:09:10 - INFO - Authentication (publickey) successful!
2024-06-14 13:09:13 - INFO - Connected (version 2.0, client OpenSSH_9.6p1)
2024-06-14 13:09:13 - INFO - Authentication (publickey) successful!
2024-06-14 13:09:45 - INFO - Connected (version 2.0, client OpenSSH_9.6p1)
2024-06-14 13:09:45 - INFO - Authentication (publickey) successful!
2024-06-14 13:11:04 - ERROR - Error getting price for c7g.12xlarge
Traceback (most recent call last):
  File "/home/miguelflj/Documentos/Mestrado/awsbench/awsbench/awsbench.py", line 189, in benchmark
    ondemand_price = aws.get_price_ondemand(region, instance_type)
  File "/home/miguelflj/Documentos/Mestrado/awsbench/awsbench/aws_bench/pricing_handler.py", line 26, in get_price_ondemand
    od = json.loads(data['PriceList'][0])['terms']['OnDemand']
IndexError: list index out of range
2024-06-14 13:11:05 - ERROR - Error in sa-east-1a: An error occurred (Unsupported) when calling the RunInstances operation: The requested configuration is currently not supported. Please check the documentation for supported configurations.
Traceback (most recent call last):
  File "/home/miguelflj/Documentos/Mestrado/awsbench/awsbench/awsbench.py", line 98, in start_instance
    instances = ec2.create_instances(
  File "/home/miguelflj/.local/lib/python3.10/site-packages/boto3/resources/factory.py", line 581, in do_action
    response = action(self, *args, **kwargs)
  File "/home/miguelflj/.local/lib/python3.10/site-packages/boto3/resources/action.py", line 88, in __call__
    response = getattr(parent.meta.client, operation_name)(*args, **params)
  File "/home/miguelflj/.local/lib/python3.10/site-packages/botocore/client.py", line 565, in _api_call
    return self._make_api_call(operation_name, kwargs)
  File "/home/miguelflj/.local/lib/python3.10/site-packages/botocore/client.py", line 1021, in _make_api_call
    raise error_class(parsed_response, operation_name)
botocore.exceptions.ClientError: An error occurred (Unsupported) when calling the RunInstances operation: The requested configuration is currently not supported. Please check the documentation for supported configurations.
2024-06-14 13:11:06 - ERROR - Error in sa-east-1b: An error occurred (Unsupported) when calling the RunInstances operation: The requested configuration is currently not supported. Please check the documentation for supported configurations.
Traceback (most recent call last):
  File "/home/miguelflj/Documentos/Mestrado/awsbench/awsbench/awsbench.py", line 98, in start_instance
    instances = ec2.create_instances(
  File "/home/miguelflj/.local/lib/python3.10/site-packages/boto3/resources/factory.py", line 581, in do_action
    response = action(self, *args, **kwargs)
  File "/home/miguelflj/.local/lib/python3.10/site-packages/boto3/resources/action.py", line 88, in __call__
    response = getattr(parent.meta.client, operation_name)(*args, **params)
  File "/home/miguelflj/.local/lib/python3.10/site-packages/botocore/client.py", line 565, in _api_call
    return self._make_api_call(operation_name, kwargs)
  File "/home/miguelflj/.local/lib/python3.10/site-packages/botocore/client.py", line 1021, in _make_api_call
    raise error_class(parsed_response, operation_name)
botocore.exceptions.ClientError: An error occurred (Unsupported) when calling the RunInstances operation: The requested configuration is currently not supported. Please check the documentation for supported configurations.
2024-06-14 13:11:07 - ERROR - Error in sa-east-1c: An error occurred (Unsupported) when calling the RunInstances operation: The requested configuration is currently not supported. Please check the documentation for supported configurations.
Traceback (most recent call last):
  File "/home/miguelflj/Documentos/Mestrado/awsbench/awsbench/awsbench.py", line 98, in start_instance
    instances = ec2.create_instances(
  File "/home/miguelflj/.local/lib/python3.10/site-packages/boto3/resources/factory.py", line 581, in do_action
    response = action(self, *args, **kwargs)
  File "/home/miguelflj/.local/lib/python3.10/site-packages/boto3/resources/action.py", line 88, in __call__
    response = getattr(parent.meta.client, operation_name)(*args, **params)
  File "/home/miguelflj/.local/lib/python3.10/site-packages/botocore/client.py", line 565, in _api_call
    return self._make_api_call(operation_name, kwargs)
  File "/home/miguelflj/.local/lib/python3.10/site-packages/botocore/client.py", line 1021, in _make_api_call
    raise error_class(parsed_response, operation_name)
botocore.exceptions.ClientError: An error occurred (Unsupported) when calling the RunInstances operation: The requested configuration is currently not supported. Please check the documentation for supported configurations.
2024-06-14 13:11:23 - ERROR - An exception occurred:Max retries reached. Could not create instance.
Traceback (most recent call last):
  File "/home/miguelflj/Documentos/Mestrado/awsbench/awsbench/awsbench.py", line 196, in benchmark
    instance = start_instance(region, instance_type)
  File "/home/miguelflj/Documentos/Mestrado/awsbench/awsbench/awsbench.py", line 138, in start_instance
    raise Exception("Max retries reached. Could not create instance.")
Exception: Max retries reached. Could not create instance.
2024-06-14 13:11:45 - INFO - Connected (version 2.0, client OpenSSH_9.6p1)
2024-06-14 13:11:45 - INFO - Authentication (publickey) successful!
2024-06-14 13:11:46 - INFO - Connected (version 2.0, client OpenSSH_9.6p1)
2024-06-14 13:11:47 - INFO - Authentication (publickey) successful!
2024-06-14 13:12:11 - INFO - Connected (version 2.0, client OpenSSH_9.6p1)
2024-06-14 13:12:11 - INFO - Authentication (publickey) successful!
2024-06-14 13:12:25 - INFO - Connected (version 2.0, client OpenSSH_9.6p1)
2024-06-14 13:12:25 - INFO - Authentication (publickey) successful!
2024-06-14 13:12:35 - INFO - Connected (version 2.0, client OpenSSH_9.6p1)
2024-06-14 13:12:35 - INFO - Authentication (publickey) successful!
2024-06-14 13:12:59 - INFO - Connected (version 2.0, client OpenSSH_9.6p1)
2024-06-14 13:12:59 - INFO - Authentication (publickey) successful!
2024-06-14 13:13:03 - INFO - Connected (version 2.0, client OpenSSH_9.6p1)
2024-06-14 13:13:03 - INFO - Authentication (publickey) successful!
2024-06-14 13:13:23 - INFO - Connected (version 2.0, client OpenSSH_9.6p1)
2024-06-14 13:13:23 - INFO - Authentication (publickey) successful!
2024-06-14 13:13:42 - INFO - Connected (version 2.0, client OpenSSH_9.6p1)
2024-06-14 13:13:42 - INFO - Authentication (publickey) successful!
2024-06-14 13:14:21 - INFO - Connected (version 2.0, client OpenSSH_9.6p1)
2024-06-14 13:14:21 - INFO - Authentication (publickey) successful!
2024-06-14 13:14:58 - INFO - Connected (version 2.0, client OpenSSH_9.6p1)
2024-06-14 13:14:58 - INFO - Authentication (publickey) successful!
2024-06-14 13:15:39 - INFO - Connected (version 2.0, client OpenSSH_9.6p1)
2024-06-14 13:15:39 - INFO - Authentication (publickey) successful!
2024-06-14 13:16:20 - INFO - Connected (version 2.0, client OpenSSH_9.6p1)
2024-06-14 13:16:20 - INFO - Authentication (publickey) successful!
2024-06-14 13:16:24 - INFO - Connected (version 2.0, client OpenSSH_9.6p1)
2024-06-14 13:16:24 - INFO - Authentication (publickey) successful!
2024-06-14 13:17:00 - INFO - Connected (version 2.0, client OpenSSH_9.6p1)
2024-06-14 13:17:01 - INFO - Authentication (publickey) successful!
2024-06-14 13:17:04 - INFO - Connected (version 2.0, client OpenSSH_9.6p1)
2024-06-14 13:17:04 - INFO - Authentication (publickey) successful!
2024-06-14 13:17:41 - INFO - Connected (version 2.0, client OpenSSH_9.6p1)
2024-06-14 13:17:41 - INFO - Authentication (publickey) successful!
2024-06-14 13:17:43 - INFO - Connected (version 2.0, client OpenSSH_9.6p1)
2024-06-14 13:17:43 - INFO - Authentication (publickey) successful!
2024-06-14 13:18:23 - INFO - Connected (version 2.0, client OpenSSH_9.6p1)
2024-06-14 13:18:23 - INFO - Authentication (publickey) successful!
2024-06-14 13:19:02 - INFO - Connected (version 2.0, client OpenSSH_9.6p1)
2024-06-14 13:19:02 - INFO - Authentication (publickey) successful!
2024-06-14 13:20:17 - INFO - Connected (version 2.0, client OpenSSH_9.6p1)
2024-06-14 13:20:18 - INFO - Authentication (publickey) successful!
2024-06-14 13:20:51 - INFO - Connected (version 2.0, client OpenSSH_9.6p1)
2024-06-14 13:20:51 - INFO - Authentication (publickey) successful!
2024-06-14 13:21:00 - INFO - Connected (version 2.0, client OpenSSH_9.6p1)
2024-06-14 13:21:01 - INFO - Authentication (publickey) successful!
2024-06-14 13:21:27 - INFO - Connected (version 2.0, client OpenSSH_9.6p1)
2024-06-14 13:21:27 - INFO - Authentication (publickey) successful!
2024-06-14 13:21:42 - INFO - Connected (version 2.0, client OpenSSH_9.6p1)
2024-06-14 13:21:43 - INFO - Authentication (publickey) successful!
2024-06-14 13:22:02 - INFO - Connected (version 2.0, client OpenSSH_9.6p1)
2024-06-14 13:22:02 - INFO - Authentication (publickey) successful!
2024-06-14 13:22:26 - INFO - Connected (version 2.0, client OpenSSH_9.6p1)
2024-06-14 13:22:27 - INFO - Authentication (publickey) successful!
2024-06-14 13:22:37 - INFO - Connected (version 2.0, client OpenSSH_9.6p1)
2024-06-14 13:22:37 - INFO - Authentication (publickey) successful!
2024-06-14 13:23:09 - INFO - Connected (version 2.0, client OpenSSH_9.6p1)
2024-06-14 13:23:10 - INFO - Authentication (publickey) successful!
2024-06-14 13:23:12 - INFO - Connected (version 2.0, client OpenSSH_9.6p1)
2024-06-14 13:23:12 - INFO - Authentication (publickey) successful!
2024-06-14 13:25:11 - INFO - Connected (version 2.0, client OpenSSH_9.6p1)
2024-06-14 13:25:11 - INFO - Authentication (publickey) successful!
2024-06-14 13:25:17 - INFO - Connected (version 2.0, client OpenSSH_9.6p1)
2024-06-14 13:25:17 - INFO - Authentication (publickey) successful!
2024-06-14 13:25:46 - INFO - Connected (version 2.0, client OpenSSH_9.6p1)
2024-06-14 13:25:47 - INFO - Authentication (publickey) successful!
2024-06-14 13:25:54 - INFO - Connected (version 2.0, client OpenSSH_9.6p1)
2024-06-14 13:25:54 - INFO - Authentication (publickey) successful!
2024-06-14 13:26:20 - INFO - Connected (version 2.0, client OpenSSH_9.6p1)
2024-06-14 13:26:20 - INFO - Authentication (publickey) successful!
2024-06-14 13:26:30 - INFO - Connected (version 2.0, client OpenSSH_9.6p1)
2024-06-14 13:26:30 - INFO - Authentication (publickey) successful!
2024-06-14 13:26:53 - INFO - Connected (version 2.0, client OpenSSH_9.6p1)
2024-06-14 13:26:53 - INFO - Authentication (publickey) successful!
2024-06-14 13:27:06 - INFO - Connected (version 2.0, client OpenSSH_9.6p1)
2024-06-14 13:27:06 - INFO - Authentication (publickey) successful!
2024-06-14 13:27:26 - INFO - Connected (version 2.0, client OpenSSH_9.6p1)
2024-06-14 13:27:26 - INFO - Authentication (publickey) successful!
2024-06-14 13:27:42 - INFO - Connected (version 2.0, client OpenSSH_9.6p1)
2024-06-14 13:27:42 - INFO - Authentication (publickey) successful!
2024-06-14 13:28:53 - INFO - Connected (version 2.0, client OpenSSH_9.6p1)
2024-06-14 13:28:53 - INFO - Authentication (publickey) successful!
2024-06-14 13:29:20 - ERROR - Error in us-east-1a: An error occurred (InsufficientInstanceCapacity) when calling the RunInstances operation (reached max retries: 4): We currently do not have sufficient c7i.12xlarge capacity in zones with support for 'gp3' volumes. Our system will be working on provisioning additional capacity.
Traceback (most recent call last):
  File "/home/miguelflj/Documentos/Mestrado/awsbench/awsbench/awsbench.py", line 98, in start_instance
    instances = ec2.create_instances(
  File "/home/miguelflj/.local/lib/python3.10/site-packages/boto3/resources/factory.py", line 581, in do_action
    response = action(self, *args, **kwargs)
  File "/home/miguelflj/.local/lib/python3.10/site-packages/boto3/resources/action.py", line 88, in __call__
    response = getattr(parent.meta.client, operation_name)(*args, **params)
  File "/home/miguelflj/.local/lib/python3.10/site-packages/botocore/client.py", line 565, in _api_call
    return self._make_api_call(operation_name, kwargs)
  File "/home/miguelflj/.local/lib/python3.10/site-packages/botocore/client.py", line 1021, in _make_api_call
    raise error_class(parsed_response, operation_name)
botocore.exceptions.ClientError: An error occurred (InsufficientInstanceCapacity) when calling the RunInstances operation (reached max retries: 4): We currently do not have sufficient c7i.12xlarge capacity in zones with support for 'gp3' volumes. Our system will be working on provisioning additional capacity.
2024-06-14 13:29:30 - INFO - Connected (version 2.0, client OpenSSH_9.6p1)
2024-06-14 13:29:30 - INFO - Authentication (publickey) successful!
2024-06-14 13:29:31 - ERROR - Error in us-east-1b: An error occurred (InsufficientInstanceCapacity) when calling the RunInstances operation (reached max retries: 4): We currently do not have sufficient c7i.12xlarge capacity in zones with support for 'gp3' volumes. Our system will be working on provisioning additional capacity.
Traceback (most recent call last):
  File "/home/miguelflj/Documentos/Mestrado/awsbench/awsbench/awsbench.py", line 98, in start_instance
    instances = ec2.create_instances(
  File "/home/miguelflj/.local/lib/python3.10/site-packages/boto3/resources/factory.py", line 581, in do_action
    response = action(self, *args, **kwargs)
  File "/home/miguelflj/.local/lib/python3.10/site-packages/boto3/resources/action.py", line 88, in __call__
    response = getattr(parent.meta.client, operation_name)(*args, **params)
  File "/home/miguelflj/.local/lib/python3.10/site-packages/botocore/client.py", line 565, in _api_call
    return self._make_api_call(operation_name, kwargs)
  File "/home/miguelflj/.local/lib/python3.10/site-packages/botocore/client.py", line 1021, in _make_api_call
    raise error_class(parsed_response, operation_name)
botocore.exceptions.ClientError: An error occurred (InsufficientInstanceCapacity) when calling the RunInstances operation (reached max retries: 4): We currently do not have sufficient c7i.12xlarge capacity in zones with support for 'gp3' volumes. Our system will be working on provisioning additional capacity.
2024-06-14 13:29:47 - ERROR - Error in us-east-1c: An error occurred (InsufficientInstanceCapacity) when calling the RunInstances operation (reached max retries: 4): We currently do not have sufficient c7i.12xlarge capacity in zones with support for 'gp3' volumes. Our system will be working on provisioning additional capacity.
Traceback (most recent call last):
  File "/home/miguelflj/Documentos/Mestrado/awsbench/awsbench/awsbench.py", line 98, in start_instance
    instances = ec2.create_instances(
  File "/home/miguelflj/.local/lib/python3.10/site-packages/boto3/resources/factory.py", line 581, in do_action
    response = action(self, *args, **kwargs)
  File "/home/miguelflj/.local/lib/python3.10/site-packages/boto3/resources/action.py", line 88, in __call__
    response = getattr(parent.meta.client, operation_name)(*args, **params)
  File "/home/miguelflj/.local/lib/python3.10/site-packages/botocore/client.py", line 565, in _api_call
    return self._make_api_call(operation_name, kwargs)
  File "/home/miguelflj/.local/lib/python3.10/site-packages/botocore/client.py", line 1021, in _make_api_call
    raise error_class(parsed_response, operation_name)
botocore.exceptions.ClientError: An error occurred (InsufficientInstanceCapacity) when calling the RunInstances operation (reached max retries: 4): We currently do not have sufficient c7i.12xlarge capacity in zones with support for 'gp3' volumes. Our system will be working on provisioning additional capacity.
2024-06-14 13:29:49 - ERROR - An exception occurred:Max retries reached. Could not create instance.
Traceback (most recent call last):
  File "/home/miguelflj/Documentos/Mestrado/awsbench/awsbench/awsbench.py", line 196, in benchmark
    instance = start_instance(region, instance_type)
  File "/home/miguelflj/Documentos/Mestrado/awsbench/awsbench/awsbench.py", line 138, in start_instance
    raise Exception("Max retries reached. Could not create instance.")
Exception: Max retries reached. Could not create instance.
2024-06-14 13:30:07 - INFO - Connected (version 2.0, client OpenSSH_9.6p1)
2024-06-14 13:30:07 - INFO - Authentication (publickey) successful!
2024-06-14 13:30:12 - INFO - Connected (version 2.0, client OpenSSH_9.6p1)
2024-06-14 13:30:13 - INFO - Authentication (publickey) successful!
2024-06-14 13:30:43 - INFO - Connected (version 2.0, client OpenSSH_9.6p1)
2024-06-14 13:30:43 - INFO - Authentication (publickey) successful!
2024-06-14 13:30:51 - INFO - Connected (version 2.0, client OpenSSH_9.6p1)
2024-06-14 13:30:52 - INFO - Authentication (publickey) successful!
2024-06-14 13:31:19 - INFO - Connected (version 2.0, client OpenSSH_9.6p1)
2024-06-14 13:31:20 - INFO - Authentication (publickey) successful!
2024-06-14 13:31:28 - INFO - Connected (version 2.0, client OpenSSH_9.6p1)
2024-06-14 13:31:29 - INFO - Authentication (publickey) successful!
2024-06-14 13:32:06 - INFO - Connected (version 2.0, client OpenSSH_9.6p1)
2024-06-14 13:32:07 - INFO - Authentication (publickey) successful!
2024-06-14 13:32:43 - INFO - Connected (version 2.0, client OpenSSH_9.6p1)
2024-06-14 13:32:44 - INFO - Authentication (publickey) successful!
2024-06-14 13:33:20 - INFO - Connected (version 2.0, client OpenSSH_9.6p1)
2024-06-14 13:33:20 - INFO - Authentication (publickey) successful!
2024-06-14 13:33:49 - INFO - Connected (version 2.0, client OpenSSH_9.6p1)
2024-06-14 13:33:49 - INFO - Authentication (publickey) successful!
2024-06-14 13:34:18 - INFO - Connected (version 2.0, client OpenSSH_9.6p1)
2024-06-14 13:34:18 - INFO - Authentication (publickey) successful!
2024-06-14 13:34:32 - INFO - Connected (version 2.0, client OpenSSH_9.6p1)
2024-06-14 13:34:32 - INFO - Authentication (publickey) successful!
2024-06-14 13:34:47 - INFO - Connected (version 2.0, client OpenSSH_9.6p1)
2024-06-14 13:34:47 - INFO - Authentication (publickey) successful!
2024-06-14 13:35:02 - INFO - Connected (version 2.0, client OpenSSH_9.6p1)
2024-06-14 13:35:03 - INFO - Authentication (publickey) successful!
2024-06-14 13:35:16 - INFO - Connected (version 2.0, client OpenSSH_9.6p1)
2024-06-14 13:35:16 - INFO - Authentication (publickey) successful!
2024-06-14 13:35:31 - INFO - Connected (version 2.0, client OpenSSH_9.6p1)
2024-06-14 13:35:32 - INFO - Authentication (publickey) successful!
2024-06-14 13:36:00 - INFO - Connected (version 2.0, client OpenSSH_9.6p1)
2024-06-14 13:36:01 - INFO - Authentication (publickey) successful!
2024-06-14 13:36:30 - INFO - Connected (version 2.0, client OpenSSH_9.6p1)
2024-06-14 13:36:30 - INFO - Authentication (publickey) successful!
2024-06-14 13:37:38 - INFO - Connected (version 2.0, client OpenSSH_9.6p1)
2024-06-14 13:37:38 - INFO - Authentication (publickey) successful!
2024-06-14 13:38:09 - INFO - Connected (version 2.0, client OpenSSH_9.6p1)
2024-06-14 13:38:09 - INFO - Authentication (publickey) successful!
2024-06-14 13:38:25 - INFO - Connected (version 2.0, client OpenSSH_9.6p1)
2024-06-14 13:38:26 - INFO - Authentication (publickey) successful!
2024-06-14 13:38:38 - INFO - Connected (version 2.0, client OpenSSH_9.6p1)
2024-06-14 13:38:38 - INFO - Authentication (publickey) successful!
2024-06-14 13:38:56 - INFO - Connected (version 2.0, client OpenSSH_9.6p1)
2024-06-14 13:38:57 - INFO - Authentication (publickey) successful!
2024-06-14 13:39:07 - INFO - Connected (version 2.0, client OpenSSH_9.6p1)
2024-06-14 13:39:07 - INFO - Authentication (publickey) successful!
2024-06-14 13:39:27 - INFO - Connected (version 2.0, client OpenSSH_9.6p1)
2024-06-14 13:39:28 - INFO - Authentication (publickey) successful!
2024-06-14 13:39:36 - INFO - Connected (version 2.0, client OpenSSH_9.6p1)
2024-06-14 13:39:36 - INFO - Authentication (publickey) successful!
2024-06-14 13:39:58 - INFO - Connected (version 2.0, client OpenSSH_9.6p1)
2024-06-14 13:39:59 - INFO - Authentication (publickey) successful!
2024-06-14 13:40:29 - INFO - Connected (version 2.0, client OpenSSH_9.6p1)
2024-06-14 13:40:30 - INFO - Authentication (publickey) successful!
2024-06-14 13:40:52 - ERROR - Error getting price for c7a.16xlarge
Traceback (most recent call last):
  File "/home/miguelflj/Documentos/Mestrado/awsbench/awsbench/awsbench.py", line 189, in benchmark
    ondemand_price = aws.get_price_ondemand(region, instance_type)
  File "/home/miguelflj/Documentos/Mestrado/awsbench/awsbench/aws_bench/pricing_handler.py", line 26, in get_price_ondemand
    od = json.loads(data['PriceList'][0])['terms']['OnDemand']
IndexError: list index out of range
2024-06-14 13:40:53 - ERROR - Error in sa-east-1a: An error occurred (Unsupported) when calling the RunInstances operation: The requested configuration is currently not supported. Please check the documentation for supported configurations.
Traceback (most recent call last):
  File "/home/miguelflj/Documentos/Mestrado/awsbench/awsbench/awsbench.py", line 98, in start_instance
    instances = ec2.create_instances(
  File "/home/miguelflj/.local/lib/python3.10/site-packages/boto3/resources/factory.py", line 581, in do_action
    response = action(self, *args, **kwargs)
  File "/home/miguelflj/.local/lib/python3.10/site-packages/boto3/resources/action.py", line 88, in __call__
    response = getattr(parent.meta.client, operation_name)(*args, **params)
  File "/home/miguelflj/.local/lib/python3.10/site-packages/botocore/client.py", line 565, in _api_call
    return self._make_api_call(operation_name, kwargs)
  File "/home/miguelflj/.local/lib/python3.10/site-packages/botocore/client.py", line 1021, in _make_api_call
    raise error_class(parsed_response, operation_name)
botocore.exceptions.ClientError: An error occurred (Unsupported) when calling the RunInstances operation: The requested configuration is currently not supported. Please check the documentation for supported configurations.
2024-06-14 13:40:53 - ERROR - Error in sa-east-1b: An error occurred (Unsupported) when calling the RunInstances operation: The requested configuration is currently not supported. Please check the documentation for supported configurations.
Traceback (most recent call last):
  File "/home/miguelflj/Documentos/Mestrado/awsbench/awsbench/awsbench.py", line 98, in start_instance
    instances = ec2.create_instances(
  File "/home/miguelflj/.local/lib/python3.10/site-packages/boto3/resources/factory.py", line 581, in do_action
    response = action(self, *args, **kwargs)
  File "/home/miguelflj/.local/lib/python3.10/site-packages/boto3/resources/action.py", line 88, in __call__
    response = getattr(parent.meta.client, operation_name)(*args, **params)
  File "/home/miguelflj/.local/lib/python3.10/site-packages/botocore/client.py", line 565, in _api_call
    return self._make_api_call(operation_name, kwargs)
  File "/home/miguelflj/.local/lib/python3.10/site-packages/botocore/client.py", line 1021, in _make_api_call
    raise error_class(parsed_response, operation_name)
botocore.exceptions.ClientError: An error occurred (Unsupported) when calling the RunInstances operation: The requested configuration is currently not supported. Please check the documentation for supported configurations.
2024-06-14 13:40:54 - ERROR - Error in sa-east-1c: An error occurred (Unsupported) when calling the RunInstances operation: The requested configuration is currently not supported. Please check the documentation for supported configurations.
Traceback (most recent call last):
  File "/home/miguelflj/Documentos/Mestrado/awsbench/awsbench/awsbench.py", line 98, in start_instance
    instances = ec2.create_instances(
  File "/home/miguelflj/.local/lib/python3.10/site-packages/boto3/resources/factory.py", line 581, in do_action
    response = action(self, *args, **kwargs)
  File "/home/miguelflj/.local/lib/python3.10/site-packages/boto3/resources/action.py", line 88, in __call__
    response = getattr(parent.meta.client, operation_name)(*args, **params)
  File "/home/miguelflj/.local/lib/python3.10/site-packages/botocore/client.py", line 565, in _api_call
    return self._make_api_call(operation_name, kwargs)
  File "/home/miguelflj/.local/lib/python3.10/site-packages/botocore/client.py", line 1021, in _make_api_call
    raise error_class(parsed_response, operation_name)
botocore.exceptions.ClientError: An error occurred (Unsupported) when calling the RunInstances operation: The requested configuration is currently not supported. Please check the documentation for supported configurations.
2024-06-14 13:41:10 - ERROR - An exception occurred:Max retries reached. Could not create instance.
Traceback (most recent call last):
  File "/home/miguelflj/Documentos/Mestrado/awsbench/awsbench/awsbench.py", line 196, in benchmark
    instance = start_instance(region, instance_type)
  File "/home/miguelflj/Documentos/Mestrado/awsbench/awsbench/awsbench.py", line 138, in start_instance
    raise Exception("Max retries reached. Could not create instance.")
Exception: Max retries reached. Could not create instance.
2024-06-14 13:41:32 - INFO - Connected (version 2.0, client OpenSSH_9.6p1)
2024-06-14 13:41:32 - INFO - Authentication (publickey) successful!
2024-06-14 13:41:58 - INFO - Connected (version 2.0, client OpenSSH_9.6p1)
2024-06-14 13:41:59 - INFO - Authentication (publickey) successful!
2024-06-14 13:42:04 - ERROR - Error in us-east-1a: An error occurred (InsufficientInstanceCapacity) when calling the RunInstances operation (reached max retries: 4): We currently do not have sufficient c7a.16xlarge capacity in zones with support for 'gp3' volumes. Our system will be working on provisioning additional capacity.
Traceback (most recent call last):
  File "/home/miguelflj/Documentos/Mestrado/awsbench/awsbench/awsbench.py", line 98, in start_instance
    instances = ec2.create_instances(
  File "/home/miguelflj/.local/lib/python3.10/site-packages/boto3/resources/factory.py", line 581, in do_action
    response = action(self, *args, **kwargs)
  File "/home/miguelflj/.local/lib/python3.10/site-packages/boto3/resources/action.py", line 88, in __call__
    response = getattr(parent.meta.client, operation_name)(*args, **params)
  File "/home/miguelflj/.local/lib/python3.10/site-packages/botocore/client.py", line 565, in _api_call
    return self._make_api_call(operation_name, kwargs)
  File "/home/miguelflj/.local/lib/python3.10/site-packages/botocore/client.py", line 1021, in _make_api_call
    raise error_class(parsed_response, operation_name)
botocore.exceptions.ClientError: An error occurred (InsufficientInstanceCapacity) when calling the RunInstances operation (reached max retries: 4): We currently do not have sufficient c7a.16xlarge capacity in zones with support for 'gp3' volumes. Our system will be working on provisioning additional capacity.
2024-06-14 13:42:18 - ERROR - Error in us-east-1b: An error occurred (InsufficientInstanceCapacity) when calling the RunInstances operation (reached max retries: 4): We currently do not have sufficient c7a.16xlarge capacity in zones with support for 'gp3' volumes. Our system will be working on provisioning additional capacity.
Traceback (most recent call last):
  File "/home/miguelflj/Documentos/Mestrado/awsbench/awsbench/awsbench.py", line 98, in start_instance
    instances = ec2.create_instances(
  File "/home/miguelflj/.local/lib/python3.10/site-packages/boto3/resources/factory.py", line 581, in do_action
    response = action(self, *args, **kwargs)
  File "/home/miguelflj/.local/lib/python3.10/site-packages/boto3/resources/action.py", line 88, in __call__
    response = getattr(parent.meta.client, operation_name)(*args, **params)
  File "/home/miguelflj/.local/lib/python3.10/site-packages/botocore/client.py", line 565, in _api_call
    return self._make_api_call(operation_name, kwargs)
  File "/home/miguelflj/.local/lib/python3.10/site-packages/botocore/client.py", line 1021, in _make_api_call
    raise error_class(parsed_response, operation_name)
botocore.exceptions.ClientError: An error occurred (InsufficientInstanceCapacity) when calling the RunInstances operation (reached max retries: 4): We currently do not have sufficient c7a.16xlarge capacity in zones with support for 'gp3' volumes. Our system will be working on provisioning additional capacity.
2024-06-14 13:42:24 - INFO - Connected (version 2.0, client OpenSSH_9.6p1)
2024-06-14 13:42:24 - INFO - Authentication (publickey) successful!
2024-06-14 13:42:40 - INFO - Connected (version 2.0, client OpenSSH_9.6p1)
2024-06-14 13:42:41 - INFO - Authentication (publickey) successful!
2024-06-14 13:42:49 - INFO - Connected (version 2.0, client OpenSSH_9.6p1)
2024-06-14 13:42:49 - INFO - Authentication (publickey) successful!
2024-06-14 13:43:10 - INFO - Connected (version 2.0, client OpenSSH_9.6p1)
2024-06-14 13:43:10 - INFO - Authentication (publickey) successful!
2024-06-14 13:43:15 - INFO - Connected (version 2.0, client OpenSSH_9.6p1)
2024-06-14 13:43:15 - INFO - Authentication (publickey) successful!
2024-06-14 13:43:38 - INFO - Connected (version 2.0, client OpenSSH_9.6p1)
2024-06-14 13:43:39 - INFO - Authentication (publickey) successful!
2024-06-14 13:44:06 - INFO - Connected (version 2.0, client OpenSSH_9.6p1)
2024-06-14 13:44:06 - INFO - Authentication (publickey) successful!
2024-06-14 13:44:34 - INFO - Connected (version 2.0, client OpenSSH_9.6p1)
2024-06-14 13:44:35 - INFO - Authentication (publickey) successful!
2024-06-14 13:45:19 - INFO - Connected (version 2.0, client OpenSSH_9.6p1)
2024-06-14 13:45:19 - INFO - Authentication (publickey) successful!
2024-06-14 13:45:48 - INFO - Connected (version 2.0, client OpenSSH_9.6p1)
2024-06-14 13:45:48 - INFO - Authentication (publickey) successful!
2024-06-14 13:46:16 - INFO - Connected (version 2.0, client OpenSSH_9.6p1)
2024-06-14 13:46:16 - INFO - Authentication (publickey) successful!
2024-06-14 13:46:35 - ERROR - Error in us-east-1a: An error occurred (InsufficientInstanceCapacity) when calling the RunInstances operation (reached max retries: 4): We currently do not have sufficient c7i.16xlarge capacity in zones with support for 'gp3' volumes. Our system will be working on provisioning additional capacity.
Traceback (most recent call last):
  File "/home/miguelflj/Documentos/Mestrado/awsbench/awsbench/awsbench.py", line 98, in start_instance
    instances = ec2.create_instances(
  File "/home/miguelflj/.local/lib/python3.10/site-packages/boto3/resources/factory.py", line 581, in do_action
    response = action(self, *args, **kwargs)
  File "/home/miguelflj/.local/lib/python3.10/site-packages/boto3/resources/action.py", line 88, in __call__
    response = getattr(parent.meta.client, operation_name)(*args, **params)
  File "/home/miguelflj/.local/lib/python3.10/site-packages/botocore/client.py", line 565, in _api_call
    return self._make_api_call(operation_name, kwargs)
  File "/home/miguelflj/.local/lib/python3.10/site-packages/botocore/client.py", line 1021, in _make_api_call
    raise error_class(parsed_response, operation_name)
botocore.exceptions.ClientError: An error occurred (InsufficientInstanceCapacity) when calling the RunInstances operation (reached max retries: 4): We currently do not have sufficient c7i.16xlarge capacity in zones with support for 'gp3' volumes. Our system will be working on provisioning additional capacity.
2024-06-14 13:46:46 - INFO - Connected (version 2.0, client OpenSSH_9.6p1)
2024-06-14 13:46:46 - INFO - Authentication (publickey) successful!
2024-06-14 13:46:51 - ERROR - Error in us-east-1b: An error occurred (InsufficientInstanceCapacity) when calling the RunInstances operation (reached max retries: 4): We currently do not have sufficient c7i.16xlarge capacity in zones with support for 'gp3' volumes. Our system will be working on provisioning additional capacity.
Traceback (most recent call last):
  File "/home/miguelflj/Documentos/Mestrado/awsbench/awsbench/awsbench.py", line 98, in start_instance
    instances = ec2.create_instances(
  File "/home/miguelflj/.local/lib/python3.10/site-packages/boto3/resources/factory.py", line 581, in do_action
    response = action(self, *args, **kwargs)
  File "/home/miguelflj/.local/lib/python3.10/site-packages/boto3/resources/action.py", line 88, in __call__
    response = getattr(parent.meta.client, operation_name)(*args, **params)
  File "/home/miguelflj/.local/lib/python3.10/site-packages/botocore/client.py", line 565, in _api_call
    return self._make_api_call(operation_name, kwargs)
  File "/home/miguelflj/.local/lib/python3.10/site-packages/botocore/client.py", line 1021, in _make_api_call
    raise error_class(parsed_response, operation_name)
botocore.exceptions.ClientError: An error occurred (InsufficientInstanceCapacity) when calling the RunInstances operation (reached max retries: 4): We currently do not have sufficient c7i.16xlarge capacity in zones with support for 'gp3' volumes. Our system will be working on provisioning additional capacity.
2024-06-14 13:47:01 - ERROR - Error in us-east-1c: An error occurred (InsufficientInstanceCapacity) when calling the RunInstances operation (reached max retries: 4): We currently do not have sufficient c7i.16xlarge capacity in zones with support for 'gp3' volumes. Our system will be working on provisioning additional capacity.
Traceback (most recent call last):
  File "/home/miguelflj/Documentos/Mestrado/awsbench/awsbench/awsbench.py", line 98, in start_instance
    instances = ec2.create_instances(
  File "/home/miguelflj/.local/lib/python3.10/site-packages/boto3/resources/factory.py", line 581, in do_action
    response = action(self, *args, **kwargs)
  File "/home/miguelflj/.local/lib/python3.10/site-packages/boto3/resources/action.py", line 88, in __call__
    response = getattr(parent.meta.client, operation_name)(*args, **params)
  File "/home/miguelflj/.local/lib/python3.10/site-packages/botocore/client.py", line 565, in _api_call
    return self._make_api_call(operation_name, kwargs)
  File "/home/miguelflj/.local/lib/python3.10/site-packages/botocore/client.py", line 1021, in _make_api_call
    raise error_class(parsed_response, operation_name)
botocore.exceptions.ClientError: An error occurred (InsufficientInstanceCapacity) when calling the RunInstances operation (reached max retries: 4): We currently do not have sufficient c7i.16xlarge capacity in zones with support for 'gp3' volumes. Our system will be working on provisioning additional capacity.
2024-06-14 13:47:03 - ERROR - An exception occurred:Max retries reached. Could not create instance.
Traceback (most recent call last):
  File "/home/miguelflj/Documentos/Mestrado/awsbench/awsbench/awsbench.py", line 196, in benchmark
    instance = start_instance(region, instance_type)
  File "/home/miguelflj/Documentos/Mestrado/awsbench/awsbench/awsbench.py", line 138, in start_instance
    raise Exception("Max retries reached. Could not create instance.")
Exception: Max retries reached. Could not create instance.
2024-06-14 13:47:17 - INFO - Connected (version 2.0, client OpenSSH_9.6p1)
2024-06-14 13:47:17 - INFO - Authentication (publickey) successful!
2024-06-14 13:47:26 - INFO - Connected (version 2.0, client OpenSSH_9.6p1)
2024-06-14 13:47:27 - INFO - Authentication (publickey) successful!
2024-06-14 13:47:55 - INFO - Connected (version 2.0, client OpenSSH_9.6p1)
2024-06-14 13:47:56 - INFO - Authentication (publickey) successful!
2024-06-14 13:48:22 - INFO - Connected (version 2.0, client OpenSSH_9.6p1)
2024-06-14 13:48:23 - INFO - Authentication (publickey) successful!
2024-06-14 13:48:50 - INFO - Connected (version 2.0, client OpenSSH_9.6p1)
2024-06-14 13:48:50 - INFO - Authentication (publickey) successful!
2024-06-14 13:49:18 - INFO - Connected (version 2.0, client OpenSSH_9.6p1)
2024-06-14 13:49:18 - INFO - Authentication (publickey) successful!
2024-06-14 15:35:38 - INFO - Start execution in us-east-1 N=5 JsonFile=instance_info.json
2024-06-14 15:36:47 - INFO - Start execution in us-east-1 N=5 JsonFile=instance_info.json
2024-06-14 15:37:04 - INFO - Start execution in us-east-1 N=5 JsonFile=instance_info.json
2024-06-17 12:53:18 - INFO - Note: NumExpr detected 32 cores but "NUMEXPR_MAX_THREADS" not set, so enforcing safe limit of 8.
2024-06-17 12:53:18 - INFO - NumExpr defaulting to 8 threads.
2024-06-17 12:53:18 - INFO - Note: NumExpr detected 32 cores but "NUMEXPR_MAX_THREADS" not set, so enforcing safe limit of 8.
2024-06-17 12:53:18 - INFO - NumExpr defaulting to 8 threads.
2024-06-17 12:53:18 - INFO - Start execution in sa-east-1 N=5 JsonFile=instance_info.json
2024-06-17 12:53:18 - INFO - Start execution in us-east-1 N=5 JsonFile=instance_info.json
2024-06-17 13:31:02 - INFO - Note: NumExpr detected 32 cores but "NUMEXPR_MAX_THREADS" not set, so enforcing safe limit of 8.
2024-06-17 13:31:02 - INFO - NumExpr defaulting to 8 threads.
2024-06-17 13:31:02 - INFO - Note: NumExpr detected 32 cores but "NUMEXPR_MAX_THREADS" not set, so enforcing safe limit of 8.
2024-06-17 13:31:02 - INFO - NumExpr defaulting to 8 threads.
2024-06-17 13:31:02 - INFO - Start execution in us-east-1 N=5 JsonFile=instance_info.json
2024-06-17 13:31:02 - INFO - Start execution in sa-east-1 N=5 JsonFile=instance_info.json
2024-06-17 13:47:44 - INFO - Note: NumExpr detected 32 cores but "NUMEXPR_MAX_THREADS" not set, so enforcing safe limit of 8.
2024-06-17 13:47:44 - INFO - NumExpr defaulting to 8 threads.
2024-06-17 13:55:36 - INFO - Note: NumExpr detected 32 cores but "NUMEXPR_MAX_THREADS" not set, so enforcing safe limit of 8.
2024-06-17 13:55:36 - INFO - NumExpr defaulting to 8 threads.
2024-06-17 14:10:32 - INFO - Note: NumExpr detected 32 cores but "NUMEXPR_MAX_THREADS" not set, so enforcing safe limit of 8.
2024-06-17 14:10:32 - INFO - NumExpr defaulting to 8 threads.
2024-06-17 15:11:29 - INFO - Note: NumExpr detected 32 cores but "NUMEXPR_MAX_THREADS" not set, so enforcing safe limit of 8.
2024-06-17 15:11:29 - INFO - NumExpr defaulting to 8 threads.
2024-06-17 15:11:29 - INFO - Start execution in sa-east-1 N=5 JsonFile=instance_infosa.json
2024-06-17 15:11:30 - ERROR - <EC2Manager>: Error to create instance
2024-06-17 15:11:30 - ERROR - 'InstanceMarketOptions'
2024-06-17 15:11:35 - ERROR - An exception occurred:'NoneType' object has no attribute 'public_ip_address'
Traceback (most recent call last):
  File "/home/miguel/Documents/awsbench/awsbench/awsbench.py", line 224, in benchmark
    output = run_via_ssh(cmd='./ep.D.x', instance=instance, region=region)
  File "/home/miguel/Documents/awsbench/awsbench/awsbench.py", line 67, in run_via_ssh
    c.connect(instance.public_ip_address,
AttributeError: 'NoneType' object has no attribute 'public_ip_address'
